<?xml version="1.0"?>
<robot xmlns:xacro="http://www.ros.org/wiki/xacro" name="raider">
  <macro name="arm" params="lr tY">

    <link name="shoulder_${lr}">
      <collision>
        <origin xyz="${tY*19.74e-3} -3.3e-3 -119.94e-3" rpy="0 0 0"/>
        <geometry>
          <mesh filename="package://raider_description/meshes/arm_${lr}/shoulder_${lr}.dae" scale="0.001 0.001 0.001"/>
        </geometry>
      </collision>
      <visual>
        <origin xyz="${tY*19.74e-3} -3.3e-3 -119.94e-3" rpy="0 0 0"/>
        <geometry>
          <mesh filename="package://raider_description/meshes/arm_${lr}/shoulder_${lr}.dae" scale="0.001 0.001 0.001"/>
        </geometry>
      </visual>
      <inertial>
        <origin xyz="${tY*-41.306133e-3} 3.409524e-3 129.948502e-3" rpy="0 0 0"/>
        <mass value="26e-3"/>
        <inertia ixx="1.1710303909e-2" ixy="${tY*-3.55401e-7}" ixz="${tY*-1.402315479e-3}" iyy="9.349656034e-3" iyz="1.85333e-7" izz="1.4505300259e-2"/>
      </inertial>
    </link>

    <joint name="shoulder_${lr}_lateral" type="revolute">
      <dynamics damping="0.0" friction="0.0"/>
      <limit upper="1.5" lower="-1.5" velocity="3" effort="100"/>
      <parent link="shoulder_${lr}"/>
      <child link="servo_upper_arm_${lr}"/>
      <origin xyz="${tY*-24e-3} 0 -1e-3" rpy="0 -0.0910695 ${tY*PI/2 + PI/2}"/>
      <axis xyz="0 1 0"/>
    </joint>

   <link name="servo_upper_arm_${lr}">
      <collision>
        <origin xyz="${tY*43.74e-3} -4e-3 -118.94e-3" rpy="0 0 0"/>
        <geometry>
          <mesh filename="package://raider_description/meshes/arm_${lr}/servo_upper_arm_${lr}.dae" scale="0.001 0.001 0.001"/>
        </geometry>
      </collision>
      <visual>
        <origin xyz="${tY*43.74e-3}  -4e-3 -118.94e-3" rpy="0 0 0"/>
        <geometry>
          <mesh filename="package://raider_description/meshes/arm_${lr}/servo_upper_arm_${lr}.dae" scale="0.001 0.001 0.001"/>
        </geometry>
      </visual>
      <inertial>
        <origin xyz="${tY*(-76.059296e-3)} 3.228505e-3 308.337189e-3" rpy="0 0 0"/>
        <mass value="${mass_servo}"/>
        <inertia ixx="${mass_servo*12008673e-3/41834.781250}" ixy="${mass_servo*tY*(-5821.5e-3)/41834.781250}" ixz="${mass_servo*tY*-470478.40625e-3/41834.781250}" iyy="${mass_servo*10172087e-3/41834.781250}" iyz="${mass_servo*(-88968.78125e-3)/41834.781250}" izz="${mass_servo*6682665e-3/41834.781250}"/>
      </inertial>
    </link>

    <joint name="joint_servo_upperarm_union1_${lr}" type="fixed">
      <dynamics damping="0.0" friction="10.0"/>
      <parent link="servo_upper_arm_${lr}"/>
      <child link="union1_servo_${lr}"/>
      <origin xyz="0 0 0" rpy="0 0 ${tY*PI/2 + PI/2}"/>
    </joint>

    <link name="union1_servo_${lr}">
      <collision>
        <origin xyz="${tY*43.74e-3} -4e-3 -118.94e-3"/>
        <geometry>
          <mesh filename="package://raider_description/meshes/arm_${lr}/union1_servo_${lr}.dae" scale="0.001 0.001 0.001"/>
        </geometry>
      </collision>
      <visual>
        <origin xyz="${tY*43.74e-3} -4e-3 -118.94e-3"/>
        <geometry>
          <mesh filename="package://raider_description/meshes/arm_${lr}/union1_servo_${lr}.dae" scale="0.001 0.001 0.001"/>
        </geometry>
      </visual>
      <inertial>
        <origin xyz="${tY*-45.191589e-3} 3.468790e-3 80.072578e-3" rpy="0 0 0"/>
        <mass value="4e-3"/>
        <inertia ixx="5.90627758e-4" ixy="${tY*1.5e-10}" ixz="${tY*1.9347738e-5}" iyy="2.51187499e-4" iyz="1.2e-7" izz="8.11914984e-4"/>
      </inertial>
    </link>

    <joint name="joint_servo_upperarm_union2_${lr}" type="fixed">
      <dynamics damping="0.0" friction="10.0"/>
      <parent link="servo_upper_arm_${lr}"/>
      <child link="union2_servo_${lr}"/>
      <origin xyz="0 0 0" rpy="0 0 ${tY*PI/2 + PI/2}"/>
    </joint>

    <link name="union2_servo_${lr}">
      <collision>
        <origin xyz="${tY*43.74e-3} -4e-3 -118.94e-3"/>
        <geometry>
          <mesh filename="package://raider_description/meshes/arm_${lr}/union2_servo_${lr}.dae" scale="0.001 0.001 0.001"/>
        </geometry>
      </collision>
      <visual>
        <origin xyz="${tY*43.74e-3} -4e-3 -118.94e-3"/>
        <geometry>
          <mesh filename="package://raider_description/meshes/arm_${lr}/union2_servo_${lr}.dae" scale="0.001 0.001 0.001"/>
        </geometry>
      </visual>
      <inertial>
        <origin xyz="${tY*-45.626991e-3} 3.451273e-3 75.296814e-3" rpy="0 0 0"/>
        <mass value="4e-3"/>
        <inertia ixx="2.55461633e-4" ixy="${tY*-1.4093e-8}" ixz="${tY*4.8831278e-5}" iyy="5.88954525e-4" iyz="-1.59133e-7" izz="8.09321022e-4"/>
      </inertial>
    </link>

    <joint name="joint_servo_elbowunion_${lr}" type="fixed">
      <dynamics damping="0.0" friction="10.0"/>
      <parent link="union2_servo_${lr}"/>
      <child link="servo_elbow_${lr}"/>
      <origin xyz="0 0 0"/>
    </joint>

    <link name="servo_elbow_${lr}">
      <collision>
        <origin xyz="${tY*43.74e-3} -4e-3 -118.94e-3"/>
        <geometry>
          <mesh filename="package://raider_description/meshes/arm_${lr}/servo_elbow_${lr}.dae" scale="0.001 0.001 0.001"/>
        </geometry>
      </collision>
      <visual>
        <origin xyz="${tY*43.74e-3} -4e-3 -118.94e-3"/>
        <geometry>
          <mesh filename="package://raider_description/meshes/arm_${lr}/servo_elbow_${lr}.dae" scale="0.001 0.001 0.001"/>
        </geometry>
      </visual>
      <inertial>
        <origin xyz="${tY*-48.971466e-3} 3.471508e-3 49.196182e-3" rpy="0 0 0"/>
        <mass value="${mass_servo}"/>
        <inertia ixx="${mass_servo*10118592e-3/41834.781250}" ixy="${mass_servo*tY*1865.812744e-3/41834.781250}" ixz="${mass_servo*tY*-392284.406250e-3/41834.781250}" iyy="${mass_servo*12037051e-3/41834.781250}" iyz="${mass_servo*(-1059.934937e-3)/41834.781250}" izz="${mass_servo*6677542e-3/41834.781250}"/>
      </inertial>
    </link>

    <joint name="elbow_${lr}" type="revolute">
      <dynamics damping="0.0" friction="0.0"/>
      <limit upper="${2*PI/3}" lower="${-2*PI/3}" velocity="3" effort="100"/>
      <parent link="servo_elbow_${lr}"/>
      <child link="elbow_${lr}"/>
      <origin xyz="0 -0.5e-3 -82.65e-3" rpy="0 0 0"/>
      <axis xyz="1 0 0"/>
    </joint>

    <link name="elbow_${lr}">
      <collision>
        <origin xyz="${tY*43.74e-3} -3.5e-3 -36.29e-3"/>
        <geometry>
          <mesh filename="package://raider_description/meshes/arm_${lr}/elbow_${lr}.dae" scale="0.001 0.001 0.001"/>
        </geometry>
      </collision>
      <visual>
        <origin xyz="${tY*43.74e-3} -3.5e-3 -36.29e-3"/>
        <geometry>
          <mesh filename="package://raider_description/meshes/arm_${lr}/elbow_${lr}.dae" scale="0.001 0.001 0.001"/>
        </geometry>
      </visual>
      <inertial>
        <origin xyz="${tY*-52.549400e-3} 7.686087e-3 26.149841e-3" rpy="0 0 0"/>
        <mass value="15e-3"/>
        <inertia ixx="4.397140534e-3" ixy="${tY*2.45999243e-4}" ixz="${tY*9.27496479e-4}" iyy="8.263120442e-3" iyz="-5.66498905e-4" izz="6.876263573e-4"/>
      </inertial>
    </link>

    <joint name="joint_elbow_forearm_${lr}" type="fixed">
      <dynamics damping="0.0" friction="10.0"/>
      <parent link="elbow_${lr}"/>
      <child link="forearm_${lr}"/>
      <origin xyz="0 0 0" rpy="0 0 0"/>
    </joint>

    <link name="forearm_${lr}">
      <collision>
        <origin xyz="${tY*43.74e-3} -3.5e-3 -36.29e-3"/>
        <geometry>
          <mesh filename="package://raider_description/meshes/arm_${lr}/forearm_${lr}.dae" scale="0.001 0.001 0.001"/>
        </geometry>
      </collision>
      <visual>
        <origin xyz="${tY*43.74e-3} -3.5e-3 -36.29e-3"/>
        <geometry>
          <mesh filename="package://raider_description/meshes/arm_${lr}/forearm_${lr}.dae" scale="0.001 0.001 0.001"/>
        </geometry>
      </visual>
      <inertial>
        <origin xyz="${tY*-53.241585e-3} 6.205578e-3 -1.415684e-3" rpy="0 0 0"/>
        <mass value="14e-3"/>
        <inertia ixx="3.440210914e-3" ixy="${tY*1.8232757e-5}" ixz="${tY*9.5159818e-5}" iyy="4.001844032e-3" iyz="2.07159085e-3" izz="4.51976604e-3"/>
      </inertial>
    </link>

    <joint name="joint_sharp_forearm_${lr}" type="fixed">
      <dynamics damping="0.0" friction="10.0"/>
      <parent link="forearm_${lr}"/>
      <child link="sharp_${lr}"/>
      <origin xyz="${tY*4.03e-3} -11.08e-3 -46.51e-3" rpy="0 0 ${-PI/2}"/>
    </joint>

    <link name="sharp_${lr}">
      <collision>
        <origin xyz="-11.08e-3 ${tY*40.97e-3} 10.22e-3" rpy="0 0 ${PI/2}"/>
        <geometry>
          <mesh filename="package://raider_description/meshes/arm_${lr}/sharp_${lr}.dae" scale="0.001 0.001 0.001"/>
        </geometry>
      </collision>
      <visual>
        <origin xyz="-11.08e-3 ${tY*40.97e-3} 10.22e-3" rpy="0 0 ${PI/2}"/>
        <geometry>
          <mesh filename="package://raider_description/meshes/arm_${lr}/sharp_${lr}.dae" scale="0.001 0.001 0.001"/>
        </geometry>
      </visual>
      <inertial>
        <origin xyz="${tY*-55.055099e-3} -1.675636e-3 -6.841179e-3" rpy="0 0 0"/>
        <mass value="3.5e-3"/>
        <inertia ixx="8.4903021e-3" ixy="${tY*9.51706e-6}" ixz="${tY*2.3015952e-3}" iyy="3.38559496e-4" iyz="6.557898e-6" izz="3.25236131e-4"/>
      </inertial>
    </link>

    <joint name="joint_forearm_hand_${lr}" type="fixed">
      <parent link="forearm_${lr}"/>
      <child link="hand_${lr}"/>
      <origin xyz="0 0 0" rpy="0 0 0"/>
    </joint>

    <link name="hand_${lr}">
      <collision>
        <origin xyz="${tY*43.74e-3} -3.5e-3 -36.29e-3"/>
        <geometry>
          <mesh filename="package://raider_description/meshes/arm_${lr}/hand_${lr}.dae" scale="0.001 0.001 0.001"/>
        </geometry>
      </collision>
      <visual>
        <origin xyz="${tY*43.74e-3} -3.5e-3 -36.29e-3"/>
        <geometry>
          <mesh filename="package://raider_description/meshes/arm_${lr}/hand_${lr}.dae" scale="0.001 0.001 0.001"/>
        </geometry>
      </visual>
      <inertial>
        <origin xyz="${tY*-57.381317e-3} 7.527186e-3 -48.516449e-3" rpy="0 0 0"/>
        <mass value="34e-3"/>
        <inertia ixx="1.3839519597e-2" ixy="${tY*-1.601312e-5}" ixz="${tY*-6.90764395e-4}" iyy="1.3107441542e-2" iyz="-1.83076833e-4" izz="6.004466355e-3"/>
      </inertial>
    </link>

  </macro>
</robot>
