<?xml version="1.0"?>
<robot xmlns:xacro="http://www.ros.org/wiki/xacro" name="raider">
  <macro name="head">

    <link name="microservo">
      <collision>
        <origin xyz="0 0 0" rpy="0 0 0"/>
        <geometry>
          <mesh filename="package://raider_description/meshes/head/microservo.dae" scale="0.001 0.001 0.001"/>
        </geometry>
      </collision>
      <visual>
        <origin xyz="0 0 0" rpy="0 0 0"/>
        <geometry>
          <mesh filename="package://raider_description/meshes/head/microservo.dae" scale="0.001 0.001 0.001"/>
        </geometry>
      </visual>
      <inertial>
        <origin xyz="-34.699566e-3 6.703261e-3 139.939987e-3" rpy="0 0 0"/>
        <mass value="13.4e-3"/>
        <inertia ixx="7.9631024e-4" ixy="7.1080342e-4" ixz="1.0505e-8" iyy="7.07342537e-4" iyz="-8.96e-10" izz="1.203373945e-3"/>
      </inertial>
    </link>

    <joint name="neck" type="revolute">
      <dynamics damping="0.0" friction="0.0"/>
      <limit upper="0" lower="-1" velocity="3" effort="100"/>
      <parent link="chest_chassis"/>
      <child link="head"/>
      <origin xyz="31.26e-3 12.1e-3 63e-3"/>
      <axis xyz="1 0 0"/>
    </joint>

    <link name="head">
      <collision>
        <origin xyz="0 -12.1e-3 -139.94e-3" rpy="0 0 0"/>
        <geometry>
          <mesh filename="package://raider_description/meshes/head/head.dae" scale="0.001 0.001 0.001"/>
        </geometry>
      </collision>
      <visual>
        <origin xyz="0 -12.1e-3 -139.94e-3" rpy="0 0 0"/>
        <geometry>
          <mesh filename="package://raider_description/meshes/head/head.dae" scale="0.001 0.001 0.001"/>
        </geometry>
      </visual>
      <inertial>
        <origin xyz="-31.180738e-3 -2.366833e-3 164.260635e-3" rpy="0 0 0"/>
        <mass value="44e-3"/>
        <inertia ixx="2.3419764683e-2" ixy="-1.7967725e-4" ixz="1.36503491e-4" iyy="1.7645258196e-2" iyz="8.30629778e-4" izz="2.6684106335e-2"/>
      </inertial>
    </link>

    <joint name="arm_microservo_joint" type="fixed">
      <dynamics damping="0.0" friction="10.0"/>
      <parent link="head"/>
      <child link="arm_microservo"/>
      <origin xyz="0 -12.1e-3 -139.94e-3"/>
    </joint>

    <link name="arm_microservo">
      <collision>
        <origin xyz="0 0 0" rpy="0 0 0"/>
        <geometry>
          <mesh filename="package://raider_description/meshes/head/arm_microservo.dae" scale="0.001 0.001 0.001"/>
        </geometry>
      </collision>
      <visual>
        <origin xyz="0 0 0" rpy="0 0 0"/>
        <geometry>
          <mesh filename="package://raider_description/meshes/head/arm_microservo.dae" scale="0.001 0.001 0.001"/>
        </geometry>
      </visual>
      <inertial>
        <origin xyz="-49.879631e-3 9.112244e-3 143.111343e-3" rpy="0 0 0"/>
        <mass value="1e-3"/>
        <inertia ixx="3.4414067e-5" ixy="-2.039668e-6" ixz="1.999204e-6" iyy="1.7986123e-5" iyz="1.4190635e-5" izz="1.857552e-5"/>
      </inertial>
    </link>

    <joint name="head_chassis_lifecam" type="fixed">
      <dynamics damping="0.0" friction="10.0"/>
      <parent link="head"/>
      <child link="chassis_lifecam"/>
      <origin xyz="0 -12.1e-3 -139.94e-3"/>
    </joint>

    <link name="chassis_lifecam">
      <collision>
        <origin xyz="0 0 0" rpy="0 0 0"/>
        <geometry>
          <mesh filename="package://raider_description/meshes/head/chassis_lifecam.dae" scale="0.001 0.001 0.001"/>
        </geometry>
      </collision>
      <visual>
        <origin xyz="0 0 0" rpy="0 0 0"/>
        <geometry>
          <mesh filename="package://raider_description/meshes/head/chassis_lifecam.dae" scale="0.001 0.001 0.001"/>
        </geometry>
      </visual>
      <inertial>
        <origin xyz="-31.209848e-3 19.280575e-3 167.859589e-3" rpy="0 0 0"/>
        <mass value="3e-3"/>
        <inertia ixx="1.51655121e-4" ixy="1.77538e-7" ixz="-1.218298e-6" iyy="3.84780168e-4" iyz="-2.85021e-7" izz="2.78011012e-4"/>
      </inertial>
    </link>
    
    <joint name="cover_head" type="fixed">
      <dynamics damping="0.0" friction="10.0"/>
      <parent link="head"/>
      <child link="cover_head"/>
      <origin xyz="0 -12.1e-3 -139.94e-3"/>
    </joint>

    <link name="cover_head">
      <collision>
        <origin xyz="0 0 0" rpy="0 0 0"/>
        <geometry>
          <mesh filename="package://raider_description/meshes/head/cover_head.dae" scale="0.001 0.001 0.001"/>
        </geometry>
      </collision>
      <visual>
        <origin xyz="0 0 0" rpy="0 0 0"/>
        <geometry>
          <mesh filename="package://raider_description/meshes/head/cover_head.dae" scale="0.001 0.001 0.001"/>
        </geometry>
      </visual>
      <inertial>
        <origin xyz="-24.260002e-3 -35.900002e-3 161.992737e-3" rpy="0 0 0"/>
        <mass value="3e-4"/>
        <inertia ixx="1.401112e-6" ixy="2e-12" ixz="-3.3e-10" iyy="1.1750281e-5" iyz="9.34e-10" izz="1.0548865e-5"/>
      </inertial>
    </link>

    <joint name="lifecam_to_chassis" type="fixed">
      <dynamics damping="0.0" friction="10.0"/>
      <parent link="chassis_lifecam"/>
      <child link="lifecam"/>
      <origin xyz="-31.5e-3 25e-3 167.9e-3" rpy="0 0 ${PI/2}"/>
    </joint>

    <link name="lifecam">
      <collision>
        <origin xyz="-25e-3 -31.5e-3 -167.9e-3" rpy="0 0 ${-PI/2}"/>
        <geometry>
          <mesh filename="package://raider_description/meshes/head/lifecam.dae" scale="0.001 0.001 0.001"/>
        </geometry>
      </collision>
      <visual>
        <origin xyz="-25e-3 -31.5e-3 -167.9e-3" rpy="0 0 ${-PI/2}"/>
        <geometry>
          <mesh filename="package://raider_description/meshes/head/lifecam.dae" scale="0.001 0.001 0.001"/>
        </geometry>
      </visual>
      <inertial>
        <origin xyz="-31.260019e-3 13.105232e-3 167.940002e-3" rpy="0 0 0"/>
        <mass value="95.3e-3"/>
        <inertia ixx="6.166010606e-3" ixy="-4.779e-9" ixz="1.9444e-8" iyy="3.256684062e-3" iyz="2.913e-9" izz="6.494934716e-3"/>
      </inertial>
    </link>
  </macro>
</robot>
