<?xml version="1.0"?>
<robot xmlns:xacro="http://www.ros.org/wiki/xacro" name="raider">
  <macro name="leg" params="lr tY">

    <joint name="ankle_${lr}_lateral" type="revolute">
      <dynamics damping="0.0" friction="0.0"/>
      <limit upper="${PI/2}" lower="${-PI/2}" velocity="3" effort="100"/>
      <parent link="back_ankle_${lr}"/>
      <child link="foot_${lr}"/>
      <origin xyz="${tY*-25e-3} 0 -1.25e-3" rpy="0 0 ${tY*PI/2 + PI/2}"/>
      <axis xyz="0 1 0"/>
    </joint>

    <link name="foot_${lr}">
      <collision>
        <origin xyz="${tY*-32e-3} 4.06e-3 173e-3" rpy="0 0 0"/>
        <geometry>
          <mesh filename="package://raider_description/meshes/leg_${lr}/foot_${lr}.dae" scale="0.001 0.001 0.001"/>
        </geometry>
      </collision>
      <visual>
        <origin xyz="${tY*-32e-3} 4.06e-3 173e-3" rpy="0 0 0"/>
        <geometry>
          <mesh filename="package://raider_description/meshes/leg_${lr}/foot_${lr}.dae" scale="0.001 0.001 0.001"/>
        </geometry>
      </visual>
      <inertial>
        <origin xyz="${tY*34.218262e-3} -2.616092e-3 -194.773895e-3" rpy="0 0 0"/>
        <mass value="31e-3"/>
        <inertia ixx="2.227440675e-2" ixy="${tY*(-3.825417e-6)}" ixz="${tY*(2.90640621e-4)}" iyy="8.364372176e-3" iyz="1.90691357e-4" izz="2.6713433444e-2"/>
      </inertial>
    </link>

    <joint name="frontankle_servofoot_${lr}" type="fixed">
      <parent link="servo_foot_${lr}"/>
      <child link="front_ankle_${lr}"/>
      <origin xyz="0 0 0"/>
    </joint>

    <link name="front_ankle_${lr}">
      <collision>
        <origin xyz="${tY*-56.94e-3} 4.06e-3 171.75e-3" rpy="0 0 0"/>
        <geometry>
          <mesh filename="package://raider_description/meshes/leg_${lr}/front_ankle_${lr}.dae" scale="0.001 0.001 0.001"/>
        </geometry>
      </collision>
      <visual>
        <origin xyz="${tY*-56.94e-3} 4.06e-3 171.75e-3" rpy="0 0 0"/>
        <geometry>
          <mesh filename="package://raider_description/meshes/leg_${lr}/front_ankle_${lr}.dae" scale="0.001 0.001 0.001"/>
        </geometry>
      </visual>
      <inertial>
        <origin xyz="${tY*32.000015} 11.489568e-3 -158.031693e-3" rpy="0 0 0"/>
        <mass value="7e-3"/>
        <inertia ixx="9.98184643e-4" ixy="${tY*9.8e-10}" ixz="${tY*4.71e-10}" 
                 iyy="1.627441646e-3" iyz="5.153015e-6" izz="6.6988573e-4"/>
      </inertial>
    </link>

    <link name="servo_foot_${lr}">
      <collision>
        <origin xyz="${tY*-56.94e-3} 4.06e-3 171.75e-3" rpy="0 0 0"/>
        <geometry>
          <mesh filename="package://raider_description/meshes/leg_${lr}/servo_foot_${lr}.dae" scale="0.001 0.001 0.001"/>
        </geometry>
      </collision>
      <visual>
        <origin xyz="${tY*-56.94e-3} 4.06e-3 171.75e-3" rpy="0 0 0"/>
        <geometry>
          <mesh filename="package://raider_description/meshes/leg_${lr}/servo_foot_${lr}.dae" scale="0.001 0.001 0.001"/>
        </geometry>
      </visual>
      <inertial>
        <origin xyz="${tY*33.059711e-3} -4.057295e-3 -160.200577e-3" rpy="0 0 0"/>
        <mass value="${mass_servo}"/>
        <inertia ixx="1.3372616303e-2" ixy="${tY*-2.572339e-6}" ixz="${tY*1.17188816e-4}" 
			iyy="1.5841409189e-2" iyz="-1.178714e-6" izz="8.731462792e-3"/>
      </inertial>
    </link>

    <joint name="joint_servo_backankle_${lr}" type="fixed">
      <origin xyz="0 0 0"/>
      <parent link="servo_foot_${lr}"/>
      <child link="back_ankle_${lr}"/>
    </joint>

    <link name="back_ankle_${lr}">
      <collision>
        <origin xyz="${tY*-56.94e-3} 4.06e-3 171.75e-3" rpy="0 0 0"/>
        <geometry>
          <mesh filename="package://raider_description/meshes/leg_${lr}/back_ankle_${lr}.dae" scale="0.001 0.001 0.001"/>
        </geometry>
      </collision>
      <visual>
        <origin xyz="${tY*-56.94e-3} 4.06e-3 171.75e-3" rpy="0 0 0"/>
        <geometry>
          <mesh filename="package://raider_description/meshes/leg_${lr}/back_ankle_${lr}.dae" scale="0.001 0.001 0.001"/>
        </geometry>
      </visual>
      <inertial>
        <origin xyz="${tY* 32.000099e-3} -25.044254e-3 -149.531372e-3" rpy="0 0 0"/>
        <mass value="5e-3"/>
        <inertia ixx="4.09812725e-4" ixy="${tY*(-5.505e-9)}" ixz="${tY*1.444e-9}" iyy="1.2913425e-3" iyz="1.3904179e-5" izz="1.050779904e-3"/>
      </inertial>
    </link>

    <joint name="servo_footback_foot_${lr}" type="fixed">
      <parent link="back_ankle_${lr}"/>
      <child link="servo_footback_${lr}"/>
      <origin xyz="0 0 0"/>
    </joint>

    <link name="servo_footback_${lr}">
      <collision>
        <origin xyz="${tY*-56.94e-3} 4.06e-3 171.75e-3" rpy="0 0 0"/>
        <geometry>
          <mesh filename="package://raider_description/meshes/leg_${lr}/servo_footback_${lr}.dae" scale="0.001 0.001 0.001"/>
        </geometry>
      </collision>
      <visual>
        <origin xyz="${tY*-56.94e-3} 4.06e-3 171.75e-3" rpy="0 0 0"/>
        <geometry>
          <mesh filename="package://raider_description/meshes/leg_${lr}/servo_footback_${lr}.dae" scale="0.001 0.001 0.001"/>
        </geometry>
      </visual>
      <inertial>
        <origin xyz="${tY*31.997292e-3} -44.940292e-3 -160.200577e-3" rpy="0 0 0"/>
        <mass value="${mass_servo}"/>
        <inertia ixx="1.5823028433e-2" ixy="${tY*2.575489e-6}" ixz="${tY*1.180097e-6}" 
			iyy="1.335689386e-2" iyz="1.14169813e-4" izz="8.722369701e-3"/>
      </inertial>
    </link>

    <joint name="ankle_${lr}_swing" type="revolute">
   <dynamics damping="0.0" friction="0.0"/>
      <limit upper="1" lower="-1" velocity="3" effort="100"/>
      <origin xyz="0 0 -75e-3" rpy="0 0 0"/>
      <parent link="lower_leg_${lr}"/>
      <child link="servo_foot_${lr}"/>
      <axis xyz="1 0 0"/>
    </joint>

    <link name="lower_leg_${lr}">
      <collision>
        <origin xyz="${tY*-56.94e-3} 4.06e-3 96.75e-3" rpy="0 0 0"/>
        <geometry>
          <mesh filename="package://raider_description/meshes/leg_${lr}/lower_leg_${lr}.dae" scale="0.001 0.001 0.001"/>
        </geometry>
      </collision>
      <visual>
        <origin xyz="${tY*-56.94e-3} 4.06e-3 96.75e-3" rpy="0 0 0"/>
        <geometry>
          <mesh filename="package://raider_description/meshes/leg_${lr}/lower_leg_${lr}.dae" scale="0.001 0.001 0.001"/>
        </geometry>
      </visual>
      <inertial>
        <origin xyz="${tY*33.664700e-3} 9.614051e-3 -125.379684e-3" rpy="0 0 0"/>
        <mass value="44e-3"/>
        <inertia ixx="4.0466879268e-2" ixy="${tY*7.67591492e-4}" ixz="${tY*9.04685905e-4}" iyy="4.9378616404e-2" iyz="-3.268945377e-3" izz="2.4910608508e-3"/>
      </inertial>
    </link>

    <joint name="lower_knee_${lr}" type="revolute">
      <dynamics damping="0.0" friction="0.0"/>
      <limit upper="${PI/2}" lower="${-PI/2}" velocity="3" effort="100"/>
      <origin xyz="0 0 -32e-3" rpy="0 0 0"/>
      <parent link="servo_lower_knee_${lr}"/>
      <child link="lower_leg_${lr}"/>
      <axis xyz="1 0 0"/>
    </joint>

    <link name="servo_lower_knee_${lr}">
      <collision>
        <origin xyz="${tY*-56.94e-3} 4.06e-3 64.75e-3" rpy="0 0 0"/>
        <geometry>
          <mesh filename="package://raider_description/meshes/leg_${lr}/servo_lower_knee_${lr}.dae" scale="0.001 0.001 0.001"/>
        </geometry>
      </collision>
      <visual>
        <origin xyz="${tY*-56.94e-3} 4.06e-3 64.75e-3" rpy="0 0 0"/>
        <geometry>
          <mesh filename="package://raider_description/meshes/leg_${lr}/servo_lower_knee_${lr}.dae" scale="0.001 0.001 0.001"/>
        </geometry>
      </visual>
      <inertial>
        <origin xyz="${tY*33.059711e-3} -16.859426e-3 -97.997299e-3" rpy="0 0 0"/>
        <mass value="${mass_servo}"/>
        <inertia ixx="1.3356996407e-4" ixy="${tY*-1.14167133e-4}" ixz="${tY*-2.564833e-3}" 
			iyy="8.722380219e-3" iyz="1.169343e-6" izz="1.5822973216e-2"/>
      </inertial>
    </link>

    <joint name="joint_servolowerknee_kneedamper1_${lr}" type="fixed">
      <origin xyz="0 0 0"/>
      <parent link="knee_damper_1_${lr}"/>
      <child link="servo_lower_knee_${lr}"/>
    </joint>

    <link name="knee_damper_1_${lr}">
      <collision>
        <origin xyz="${tY*-56.94e-3} 4.06e-3 64.75e-3" rpy="0 0 0"/>
        <geometry>
          <mesh filename="package://raider_description/meshes/leg_${lr}/knee_damper${lr}_1.dae" scale="0.001 0.001 0.001"/>
        </geometry>
      </collision>
      <visual>
        <origin xyz="${tY*-56.94e-3} 4.06e-3 64.75e-3" rpy="0 0 0"/>
        <geometry>
          <mesh filename="package://raider_description/meshes/leg_${lr}/knee_damper${lr}_1.dae" scale="0.001 0.001 0.001"/>
        </geometry>
      </visual>
      <inertial>
        <origin xyz="${tY*49.524082e-3} -31.720390e-3 -78.538048e-3" rpy="0 0 0"/>
        <mass value="2e-3"/>
        <inertia ixx="4.23026673e-4" ixy="${tY*7.535722e-6}" ixz="${tY*-2.01741e-6}" iyy="1.36987356e-4" iyz="6.7385341e-5" izz="2.90494473e-4"/>
      </inertial>
    </link>

    <link name="knee_damper_2_${lr}">
      <collision>
        <origin xyz="${tY*-56.94e-3} 4.06e-3 64.75e-3" rpy="0 0 0"/>
        <geometry>
          <mesh filename="package://raider_description/meshes/leg_${lr}/knee_damper${lr}_2.dae" scale="0.001 0.001 0.001"/>
        </geometry>
      </collision>
      <visual>
        <origin xyz="${tY*-56.94e-3} 4.06e-3 64.75e-3" rpy="0 0 0"/>
        <geometry>
          <mesh filename="package://raider_description/meshes/leg_${lr}/knee_damper${lr}_2.dae" scale="0.001 0.001 0.001"/>
        </geometry>
      </visual>
      <inertial>
        <origin xyz="${tY*14.675918e-3} -31.720392e-3 -78.538040e-3" rpy="0 0 0"/>
        <mass value="2e-3"/>
        <inertia ixx="4.23030511e-4" ixy="${tY*7.535441e-6}" ixz="${tY*-2.017274e-3}" 
			iyy="1.36991903e-4" iyz="6.7384774e-5" izz="2.90495255e-4"/>
      </inertial>
    </link>

    <joint name="joint_damper2leg_servoupperknee_${lr}" type="fixed">
      <origin xyz="0 0 0"/>
      <parent link="servo_upper_knee_${lr}"/>
      <child link="knee_damper_2_${lr}"/>
    </joint>

    <joint name="joint_damper1leg_servoupperknee_${lr}" type="fixed">
      <origin xyz="0 0 0"/>
      <parent link="servo_upper_knee_${lr}"/>
      <child link="knee_damper_1_${lr}"/>
    </joint>

    <link name="servo_upper_knee_${lr}">
      <collision>
        <origin xyz="${tY*-56.94e-3} 4.06e-3 64.75e-3" rpy="0 0 0"/>
        <geometry>
          <mesh filename="package://raider_description/meshes/leg_${lr}/servo_upper${lr}_knee.dae" scale="0.001 0.001 0.001"/>
        </geometry>
      </collision>
      <visual>
        <origin xyz="${tY*-56.94e-3} 4.06e-3 64.75e-3" rpy="0 0 0"/>
        <geometry>
          <mesh filename="package://raider_description/meshes/leg_${lr}/servo_upper${lr}_knee.dae" scale="0.001 0.001 0.001"/>
        </geometry>
      </visual>
      <inertial>
        <origin xyz="${tY*33.059711e-3} -16.859426e-3 -65.997299e-3" rpy="0 0 0"/>
        <mass value="${mass_servo}"/>
        <inertia ixx="1.3372655744e-2" ixy="${tY*-1.1718175e-4}" ixz="${tY*2.571199e-6}"
			iyy="8.731482512e-3" iyz="1.172656e-6" izz="1.5841505162e-2"/>
      </inertial>
    </link>

    <joint name="upper_knee_${lr}" type="revolute">
      <dynamics damping="0.0" friction="0.0"/>
      <origin xyz="0 0 -73.75e-3" rpy="0 0 0"/>
      <limit upper="${PI/2}" lower="${-PI/2}" velocity="3" effort="100"/>
      <parent link="upper_leg_${lr}"/>
      <child link="servo_upper_knee_${lr}"/>
    </joint>

    <link name="upper_leg_${lr}">
      <collision>
        <origin xyz="${tY*-56.94e-3} 4.06e-3 -9e-3" rpy="0 0 0"/>
        <geometry>
          <mesh filename="package://raider_description/meshes/leg_${lr}/upper_leg_${lr}.dae" scale="0.001 0.001 0.001"/>
        </geometry>
      </collision>
      <visual>
        <origin xyz="${tY*-56.94e-3} 4.06e-3 -9e-3" rpy="0 0 0"/>
        <geometry>
          <mesh filename="package://raider_description/meshes/leg_${lr}/upper_leg_${lr}.dae" scale="0.001 0.001 0.001"/>
        </geometry>
      </visual>
      <inertial>
        <origin xyz="${tY*33.380638e-3} -0.118964e-3 -33.265591e-3" rpy="0 0 0"/>
        <mass value="23e-3"/>
        <inertia ixx="1.6287494127e-2" ixy="${tY*3.9940722e-5}" ixz="${tY*(-4.8285696e-5)}" iyy="2.4786351073e-4" iyz="1.256185001e-3" izz="1.2170186251e-2"/>
      </inertial>
    </link>

    <joint name="hip_${lr}_swing" type="revolute">
      <dynamics damping="0.0" friction="0.0"/>
      <limit upper="${PI/2}" lower="${-PI/2}" velocity="3" effort="100"/>
      <origin xyz="${tY*24.94e-3} 56.94e-3 0" rpy="0 0 0"/>
      <parent link="servo_upper_front_${lr}"/>
      <child link="upper_leg_${lr}"/>
    </joint>

    <link name="servo_upper_front_${lr}">
      <collision>
        <origin xyz="${tY*-32e-3} 61e-3 -9e-3" rpy="0 0 0"/>
        <geometry>
          <mesh filename="package://raider_description/meshes/leg_${lr}/servo_upper${lr}_front.dae" scale="0.001 0.001 0.001"/>
        </geometry>
      </collision>
      <visual>
        <origin xyz="${tY*-32e-3} 61e-3 -9e-3" rpy="0 0 0"/>
        <geometry>
          <mesh filename="package://raider_description/meshes/leg_${lr}/servo_upper${lr}_front.dae" scale="0.001 0.001 0.001"/>
        </geometry>
      </visual>
      <inertial>
        <origin xyz="${tY*33.259712e-3} -4.062710e-3 -3.799430e-3" rpy="0 0 0"/>
        <mass value="${mass_servo}"/>
        <inertia ixx="1.3372630764e-2" ixy="${tY*2.572295e-6}" ixz="${tY*-1.17182951e-4}" 
			iyy="1.5841502533e-2" iyz="-1.180558e-6" izz="8.731446358e-3"/>
      </inertial>
    </link>

    <joint name="joint_servoupperfront_tob${lr}" type="fixed">
      <origin xyz="0 0 0"/>
      <parent link="servo_upper_front_${lr}"/>
      <child link="tob_${lr}"/>
    </joint>

    <link name="tob_${lr}">
      <collision>
        <origin xyz="${tY*-32e-3} 61e-3 -9e-3" rpy="0 0 0"/>
        <geometry>
          <mesh filename="package://raider_description/meshes/leg_${lr}/tob_${lr}.dae" scale="0.001 0.001 0.001"/>
        </geometry>
      </collision>
      <visual>
        <origin xyz="${tY*-32e-3} 61e-3 -9e-3" rpy="0 0 0"/>
        <geometry>
          <mesh filename="package://raider_description/meshes/leg_${lr}/tob_${lr}.dae" scale="0.001 0.001 0.001"/>
        </geometry>
      </visual>
      <inertial>
        <origin xyz="${tY*31.999987e-3} 12.549569e-3 -5.968293e-3" rpy="0 0 0"/>
        <mass value="7e-3"/>
        <inertia ixx="9.98184661e-4" ixy="${tY*-1.004e-9}" ixz="${tY*1.021e-9}" iyy="1.627441646e-3" iyz="-5.152814e-3" izz="6.69885346e-4"/>
      </inertial>
    </link>

    <joint name="joint${lr}_servoupperfront_groin2" type="fixed">
      <origin xyz="0 0 0"/>
      <parent link="groin2_${lr}"/>
      <child link="servo_upper_front_${lr}"/>
    </joint>

    <link name="groin2_${lr}">
      <collision>
        <origin xyz="${tY*-32e-3} 61e-3 -9e-3" rpy="0 0 0"/>
        <geometry>
          <mesh filename="package://raider_description/meshes/leg_${lr}/groin2_${lr}.dae" scale="0.001 0.001 0.001"/>
        </geometry>
      </collision>
      <visual>
        <origin xyz="${tY*-32e-3} 61e-3 -9e-3" rpy="0 0 0"/>
        <geometry>
          <mesh filename="package://raider_description/meshes/leg_${lr}/groin2_${lr}.dae" scale="0.001 0.001 0.001"/>
        </geometry>
      </visual>
      <inertial>
        <origin xyz="${tY*16.159353e-3} -35.801258e-3 -7.292182e-3" rpy="0 0 0"/>
        <mass value="5e-3"/>
        <inertia ixx="9.64450567e-4" ixy="${tY*(-3.2521998e-5)}" ixz="${tY*3.002097e-6}" iyy="3.77541101e-4" iyz="8.8795829e-5" izz="6.12968817e-4"/>
      </inertial>
    </link>

    <joint name="joint${lr}_servoupperback_groin1" type="fixed">
      <origin xyz="0 ${tY*21.89e-3 + 21.89e-3} 0" rpy="0 0 ${-tY*PI/2 - PI/2}"/>
      <parent link="servo_upper_back_${lr}"/>
      <child link="groin2_${lr}"/>
    </joint>

    <link name="groin1_${lr}">
      <collision>
        <origin xyz="${tY*-32e-3} 61e-3 -9e-3" rpy="0 0 0"/>
        <geometry>
          <mesh filename="package://raider_description/meshes/leg_${lr}/groin1_${lr}.dae" scale="0.001 0.001 0.001"/>
        </geometry>
      </collision>
      <visual>
        <origin xyz="${tY*-32e-3} 61e-3 -9e-3" rpy="0 0 0"/>
        <geometry>
          <mesh filename="package://raider_description/meshes/leg_${lr}/groin1_${lr}.dae" scale="0.001 0.001 0.001"/>
        </geometry>
      </visual>
      <inertial>
        <origin xyz="${tY*47.840645e-3} -35.801262e-3 -7.292187e-3" rpy="0 0 0"/>
        <mass value="5e-3"/>
        <inertia ixx="9.64451283e-4" ixy="${tY*3.2521697e-5}" ixz="${tY*(-3.002165e-6)}" iyy="3.77541141e-4" iyz="8.879578e-5" izz="6.12969334e-4"/>
      </inertial>
    </link>

    <joint name="joint_servoupperback_groin1_${lr}" type="fixed">
      <origin xyz="0 ${tY*21.89e-3 + 21.89e-3} 0" rpy="0 0 ${-tY*PI/2 - PI/2}"/>
      <parent link="servo_upper_back_${lr}"/>
      <child link="groin1_${lr}"/>
    </joint>

    <link name="servo_upper_back_${lr}">
      <collision>
        <origin xyz="${tY*-32e-3} 61e-3 -9e-3" rpy="0 0 0"/>
        <geometry>
          <mesh filename="package://raider_description/meshes/leg_${lr}/servo_upper${lr}_back.dae" scale="0.001 0.001 0.001"/>
        </geometry>
      </collision>
      <visual>
        <origin xyz="${tY*-32e-3} 61e-3 -9e-3" rpy="0 0 0"/>
        <geometry>
          <mesh filename="package://raider_description/meshes/leg_${lr}/servo_upper${lr}_back.dae" scale="0.001 0.001 0.001"/>
        </geometry>
      </visual>
      <inertial>
        <origin xyz="${tY*32.002708e-3} -41.380287e-3 -3.799424e-3" rpy="0 0 0"/>
        <mass value="${mass_servo}"/>
        <inertia ixx="1.5841507791e-2" ixy="${tY*-2.568826e-6}" ixz="${tY*1.180211e-6}"
			iyy="1.3372622876e-2" iyz="-1.17182284e-4" izz="8.731452274e-3"/>
      </inertial>
    </link>

    <joint name="groin_${lr}" type="revolute">
      <limit upper="${PI/2}" lower="${-PI/2}" velocity="3" effort="100"/>
      <origin xyz="0 ${tY*21.89e-3 - 18.11e-3} ${tY*-22e-3}" rpy="0 ${tY*PI/2 - PI/2} ${tY*PI/2 + PI/2}"/>
      <parent link="leg_bracket_${lr}"/>
      <child link="servo_upper_back_${lr}"/>
      <axis xyz="0 1 0"/>
    </joint>

    <link name="leg_bracket_${lr}">
      <collision>
        <origin xyz="${tY*-32e-3} 21e-3 -31e-3" rpy="0 0 0"/>
        <geometry>
          <mesh filename="package://raider_description/meshes/leg_${lr}/leg_bracket_${lr}.dae" scale="0.001 0.001 0.001"/>
        </geometry>
      </collision>
      <visual>
        <origin xyz="${tY*-32e-3} 21e-3 -31e-3" rpy="0 0 0"/>
        <geometry>
          <mesh filename="package://raider_description/meshes/leg_${lr}/leg_bracket_${lr}.dae" scale="0.001 0.001 0.001"/>
        </geometry>
      </visual>
      <inertial>
        <origin xyz="${tY*31.468872e-3} -22.709967e-3 27.662817e-3" rpy="0 0 0"/>
        <mass value="17e-3"/>
        <inertia ixx="1.953408409e-2" ixy="${tY*2.36958746e-4}" ixz="${tY*8.1847589e-5}" iyy="2.81864658e-4" iyz="-3.18501245e-4" izz="1.4972208875e-2"/>
      </inertial>
    </link>

  </macro>
</robot>
