<?xml version="1.0" ?>
<!-- =================================================================================== -->
<!-- |    This document was autogenerated by xacro from raider.xacro                   | -->
<!-- |    EDITING THIS FILE BY HAND IS NOT RECOMMENDED                                 | -->
<!-- =================================================================================== -->
<robot name="raider" xmlns:xacro="http://www.ros.org/wiki/xacro">
  <selfCollide>true</selfCollide>
  <!-- Head materials-->
  <gazebo reference="arm_microservo">
    <!--mu1>0.5</mu1>
      <mu2>100</mu2>
      <selfCollide>false</selfCollide>
      <turnGravityOff>true</turnGravityOff>
      <mu1>100</mu1>
      <mu2>100</mu2-->
    <material>Gazebo/DarkGrey</material>
  </gazebo>
  <gazebo reference="head">
    <!--mu1>0.5</mu1>
      <mu2>100</mu2>
      <selfCollide>false</selfCollide>
      <turnGravityOff>true</turnGravityOff>
      <mu1>100</mu1>
      <mu2>100</mu2-->
    <material>Gazebo/Red</material>
  </gazebo>
  <gazebo reference="lifecam">
    <!--mu1>0.5</mu1>
      <mu2>100</mu2>
      <selfCollide>false</selfCollide>
      <turnGravityOff>true</turnGravityOff>
      <mu1>100</mu1>
      <mu2>100</mu2-->
    <material>Gazebo/Orange</material>
  </gazebo>
  <gazebo reference="microservo">
    <!--mu1>0.5</mu1>
      <mu2>100</mu2>
      <selfCollide>false</selfCollide>
      <turnGravityOff>true</turnGravityOff>
      <mu1>100</mu1>
      <mu2>100</mu2-->
    <material>Gazebo/FlatBlack</material>
  </gazebo>
  <gazebo reference="chassis_lifecam">
    <!--mu1>0.5</mu1>
      <mu2>100</mu2>
      <selfCollide>false</selfCollide>
      <turnGravityOff>true</turnGravityOff>
      <mu1>100</mu1>
      <mu2>100</mu2-->
    <!--material>Gazebo/DarkGrey</material-->
  </gazebo>
  <!-- LifeCam plugin -->
  <gazebo reference="lifecam">
    <sensor name="camera1" type="camera">
      <update_rate>30.0</update_rate>
      <camera name="head">
        <horizontal_fov>1.27409</horizontal_fov>
        <image>
          <width>1280</width>
          <height>720</height>
          <format>R8G8B8</format>
        </image>
        <clip>
          <near>0.001</near>
          <far>3</far>
        </clip>
        <noise>
          <type>gaussian</type>
          <!-- Noise is sampled independently per pixel on each frame.
               That pixel's noise value is added to each of its color
               channels, which at that point lie in the range [0,1]. -->
          <mean>0.0</mean>
          <stddev>0.007</stddev>
        </noise>
      </camera>
      <plugin filename="libgazebo_ros_camera.so" name="camera_controller">
        <alwaysOn>true</alwaysOn>
        <updateRate>30.0</updateRate>
        <cameraName>RAIDER/LifeCam</cameraName>
        <imageTopicName>image_raw</imageTopicName>
        <cameraInfoTopicName>camera_info</cameraInfoTopicName>
        <frameName>lifecam</frameName>
        <hackBaseline>0.07</hackBaseline>
        <distortionK1>0.0</distortionK1>
        <distortionK2>0.0</distortionK2>
        <distortionK3>0.0</distortionK3>
        <distortionT1>0.0</distortionT1>
        <distortionT2>0.0</distortionT2>
      </plugin>
    </sensor>
  </gazebo>
  <!--Sonar plugin-->
  <gazebo reference="ultrasonic_sensor">
    <sensor name="sonar" type="ray">
      <pose>0 0 0 0 0 0</pose>
      <update_rate>5</update_rate>
      <visualize>false</visualize>
      <ray>
        <scan>
          <horizontal>
            <samples>5</samples>
            <resolution>1.0</resolution>
            <min_angle>-0.261799387799</min_angle>
            <max_angle>0.261799387799</max_angle>
          </horizontal>
          <vertical>
            <samples>5</samples>
            <resolution>1.0</resolution>
            <min_angle>-0.261799387799</min_angle>
            <max_angle>0.261799387799</max_angle>
          </vertical>
        </scan>
        <range>
          <min>0.02</min>
          <max>4</max>
          <resolution>0.003</resolution>
        </range>
      </ray>
      <plugin filename="libgazebo_ros_range.so" name="gazebo_ros_range">
        <gaussianNoise>0.005</gaussianNoise>
        <alwaysOn>true</alwaysOn>
        <updateRate>5</updateRate>
        <topicName>sonar</topicName>
        <frameName>ultrasonic_sensor</frameName>
        <fov>0.5</fov>
        <radiation>ultrasound</radiation>
      </plugin>
    </sensor>
  </gazebo>
  <!--Infrared plugin-->
  <gazebo reference="sharp_right">
    <sensor name="sharp_right" type="ray">
      <pose>0 0 0 0 0 0</pose>
      <update_rate>5</update_rate>
      <visualize>false</visualize>
      <ray>
        <range>
          <min>0.02</min>
          <max>4</max>
          <resolution>0.003</resolution>
        </range>
      </ray>
      <plugin filename="libgazebo_ros_range.so" name="gazebo_ros_range_sharpright">
        <gaussianNoise>0.005</gaussianNoise>
        <alwaysOn>true</alwaysOn>
        <updateRate>5</updateRate>
        <topicName>sharp_right</topicName>
        <frameName>sharp_right</frameName>
        <fov>0.5</fov>
        <radiation>infrared</radiation>
      </plugin>
    </sensor>
  </gazebo>
  <gazebo reference="sharp_left">
    <sensor name="sharp_left" type="ray">
      <pose>0 0 0 0 0 0</pose>
      <update_rate>5</update_rate>
      <visualize>false</visualize>
      <ray>
        <range>
          <min>0.02</min>
          <max>4</max>
          <resolution>0.003</resolution>
        </range>
      </ray>
      <plugin filename="libgazebo_ros_range.so" name="gazebo_ros_range_sharpleft">
        <gaussianNoise>0.005</gaussianNoise>
        <alwaysOn>true</alwaysOn>
        <updateRate>5</updateRate>
        <topicName>sharp_left</topicName>
        <frameName>sharp_left</frameName>
        <fov>0.5</fov>
        <radiation>infrared</radiation>
      </plugin>
    </sensor>
  </gazebo>
  <!--IMU sensors-->
  <gazebo>
    <plugin filename="libhector_gazebo_ros_imu.so" name="imu_controller">
      <robotNamespace>/</robotNamespace>
      <updateRate>50.0</updateRate>
      <bodyName>accelerometer</bodyName>
      <topicName>imu_accelerometer/data</topicName>
      <accelDrift>0.005 0.005 0.005</accelDrift>
      <accelGaussianNoise>0.005 0.005 0.005</accelGaussianNoise>
      <rateDrift>0.005 0.005 0.005 </rateDrift>
      <rateGaussianNoise>0.005 0.005 0.005 </rateGaussianNoise>
      <headingDrift>0.005</headingDrift>
      <headingGaussianNoise>0.005</headingGaussianNoise>
    </plugin>
  </gazebo>
  <gazebo>
    <plugin filename="libhector_gazebo_ros_imu.so" name="imu_controller">
      <robotNamespace>/</robotNamespace>
      <updateRate>50.0</updateRate>
      <bodyName>compass</bodyName>
      <topicName>imu_compass/data</topicName>
      <accelDrift>0.005 0.005 0.005</accelDrift>
      <accelGaussianNoise>0.005 0.005 0.005</accelGaussianNoise>
      <rateDrift>0.005 0.005 0.005 </rateDrift>
      <rateGaussianNoise>0.005 0.005 0.005 </rateGaussianNoise>
      <headingDrift>0.005</headingDrift>
      <headingGaussianNoise>0.005</headingGaussianNoise>
    </plugin>
  </gazebo>
  <!-- Chest materials-->
  <gazebo reference="chest_chassis">
    <!--mu1>0.5</mu1>
      <mu2>50</mu2>
      <selfCollide>false</selfCollide>
      <turnGravityOff>true</turnGravityOff-->
    <selfCollide>false</selfCollide>
  </gazebo>
  <gazebo reference="servo_shoulder_right">
    <!--mu1>0.5</mu1>
      <mu2>50</mu2>
      <selfCollide>false</selfCollide>
      <turnGravityOff>true</turnGravityOff-->
    <material>Gazebo/DarkGrey</material>
  </gazebo>
  <gazebo reference="cover_head">
    <!--mu1>0.5</mu1>
      <mu2>100</mu2>
      <selfCollide>false</selfCollide>
      <turnGravityOff>true</turnGravityOff-->
    <material>Gazebo/DarkGrey</material>
  </gazebo>
  <gazebo reference="compass">
    <!--mu1>0.5</mu1>
      <mu2>100</mu2>
      <selfCollide>false</selfCollide>
      <turnGravityOff>true</turnGravityOff-->
    <material>Gazebo/Grass</material>
  </gazebo>
  <gazebo reference="servo_shoulder_left">
    <!--mu1>0.5</mu1>
      <mu2>100</mu2>
      <selfCollide>false</selfCollide>
      <turnGravityOff>true</turnGravityOff-->
    <material>Gazebo/DarkGrey</material>
  </gazebo>
  <gazebo reference="battery">
    <!--mu1>0.5</mu1>
      <mu2>100</mu2>
      <selfCollide>false</selfCollide>
      <turnGravityOff>true</turnGravityOff-->
    <material>Gazebo/Yellow</material>
  </gazebo>
  <gazebo reference="ultrasonic_sensor">
    <!--mu1>0.5</mu1>
      <mu2>100</mu2>
      <selfCollide>false</selfCollide>
      <turnGravityOff>true</turnGravityOff-->
    <material>Gazebo/BlueEmissive</material>
  </gazebo>
  <gazebo reference="ubec">
    <!--mu1>0.5</mu1>
      <mu2>100</mu2>
      <selfCollide>false</selfCollide>
      <turnGravityOff>true</turnGravityOff-->
    <material>Gazebo/BlueEmissive</material>
  </gazebo>
  <gazebo reference="accelerometer">
    <!--mu1>0.5</mu1>
      <mu2>100</mu2>
      <selfCollide>false</selfCollide>
      <turnGravityOff>true</turnGravityOff-->
    <material>Gazebo/Grass</material>
  </gazebo>
  <gazebo reference="expansion_board">
    <!--mu1>0.5</mu1>
      <mu2>100</mu2>
      <selfCollide>false</selfCollide>
      <turnGravityOff>true</turnGravityOff-->
    <material>Gazebo/Gold</material>
  </gazebo>
  <!-- Hip materials-->
  <gazebo reference="servo_hip_right">
    <!--mu1>0.5</mu1>
      <mu2>100</mu2>
      <selfCollide>false</selfCollide>
      <turnGravityOff>true</turnGravityOff-->
    <selfCollide>false</selfCollide>
    <material>Gazebo/DarkGrey</material>
  </gazebo>
  <gazebo reference="servo_hip_left">
    <!--mu1>0.5</mu1>
      <mu2>100</mu2>
      <selfCollide>false</selfCollide>
      <turnGravityOff>true</turnGravityOff-->
    <selfCollide>false</selfCollide>
    <material>Gazebo/DarkGrey</material>
  </gazebo>
  <gazebo reference="servo_hip_middle">
    <!--mu1>0.5</mu1>
      <mu2>100</mu2>
      <selfCollide>false</selfCollide>
      <turnGravityOff>true</turnGravityOff-->
    <material>Gazebo/DarkGrey</material>
  </gazebo>
  <gazebo reference="upper_hip">
    <!--mu1>0.5</mu1>
      <mu2>100</mu2>
      <selfCollide>false</selfCollide>
      <turnGravityOff>true</turnGravityOff-->
    <material>Gazebo/Red</material>
  </gazebo>
  <gazebo reference="hip_chassis">
    <!--mu1>0.5</mu1>
      <mu2>100</mu2>
      <selfCollide>false</selfCollide>
      <turnGravityOff>true</turnGravityOff-->
    <material>Gazebo/DarkGrey</material>
  </gazebo>
  <!-- Arm materials-->
  <gazebo reference="shoulder_left">
    <!--mu1>200</mu1>
      <mu2>200</mu2-->
    <material>Gazebo/Red</material>
  </gazebo>
  <gazebo reference="shoulder_right">
    <!--mu1>200</mu1>
      <mu2>200</mu2-->
    <material>Gazebo/Red</material>
  </gazebo>
  <gazebo reference="elbow_left">
    <!--mu1>200</mu1>
      <mu2>200</mu2-->
    <material>Gazebo/Red</material>
  </gazebo>
  <gazebo reference="elbow_right">
    <!--mu1>200</mu1>
      <mu2>200</mu2-->
    <material>Gazebo/Red</material>
  </gazebo>
  <gazebo reference="servo_upper_arm_left">
    <!--mu1>200</mu1>
      <mu2>200</mu2-->
    <selfCollide>false</selfCollide>
    <material>Gazebo/DarkGrey</material>
  </gazebo>
  <gazebo reference="servo_upper_arm_right">
    <!--mu1>200</mu1>
      <mu2>200</mu2-->
    <selfCollide>false</selfCollide>
    <material>Gazebo/DarkGrey</material>
  </gazebo>
  <gazebo reference="servo_elbow_left">
    <!--mu1>200</mu1>
      <mu2>200</mu2-->
    <selfCollide>false</selfCollide>
    <material>Gazebo/DarkGrey</material>
  </gazebo>
  <gazebo reference="servo_elbow_right">
    <!--mu1>200</mu1>
      <mu2>200</mu2-->
    <selfCollide>false</selfCollide>
    <material>Gazebo/DarkGrey</material>
  </gazebo>
  <gazebo reference="forearm_left">
    <!--mu1>200</mu1>
      <mu2>200</mu2-->
    <material>Gazebo/DarkGrey</material>
  </gazebo>
  <gazebo reference="forearm_right">
    <!--mu1>200</mu1>
      <mu2>200</mu2-->
    <material>Gazebo/DarkGrey</material>
  </gazebo>
  <gazebo reference="hand_left">
    <!--mu1>200</mu1>
      <mu2>200</mu2-->
    <selfCollide>false</selfCollide>
    <material>Gazebo/Red</material>
  </gazebo>
  <gazebo reference="hand_right">
    <!--mu1>200</mu1>
      <mu2>200</mu2-->
    <selfCollide>false</selfCollide>
    <material>Gazebo/Red</material>
  </gazebo>
  <gazebo reference="union2_servo_left">
    <!--mu1>200</mu1>
      <mu2>200</mu2-->
    <material>Gazebo/Red</material>
  </gazebo>
  <gazebo reference="union2_servo_right">
    <!--mu1>200</mu1>
      <mu2>200</mu2-->
    <material>Gazebo/Red</material>
  </gazebo>
  <gazebo reference="union1_servo_left">
    <!--mu1>200</mu1>
      <mu2>200</mu2-->
    <material>Gazebo/Red</material>
  </gazebo>
  <gazebo reference="union1_servo_right">
    <!--mu1>200</mu1>
      <mu2>200</mu2-->
    <material>Gazebo/Red</material>
  </gazebo>
  <!-- Leg materials-->
  <gazebo reference="servo_foot_left">
    <!--mu1>0.5</mu1>
      <mu2>50</mu2>
      <selfCollide>false</selfCollide>
      <turnGravityOff>true</turnGravityOff-->
    <!--selfCollide>true</selfCollide-->
    <!--mu1>200</mu1>
      <mu2>200</mu2-->
    <material>Gazebo/DarkGrey</material>
  </gazebo>
  <gazebo reference="servo_foot_right">
    <!--mu1>0.5</mu1>
      <mu2>50</mu2>
      <selfCollide>false</selfCollide>
      <turnGravityOff>true</turnGravityOff-->
    <!--selfCollide>true</selfCollide-->
    <!--mu1>200</mu1>
      <mu2>200</mu2-->
    <material>Gazebo/DarkGrey</material>
  </gazebo>
  <gazebo reference="servo_lower_knee_left">
    <!--mu1>0.5</mu1>
      <mu2>200</mu2>
      <selfCollide>false</selfCollide>
      <turnGravityOff>true</turnGravityOff-->
    <!--mu1>200</mu1>
      <mu2>200</mu2-->
    <!--selfCollide>true</selfCollide-->
    <material>Gazebo/DarkGrey</material>
  </gazebo>
  <gazebo reference="servo_lower_knee_right">
    <!--mu1>0.5</mu1>
      <mu2>200</mu2>
      <selfCollide>false</selfCollide>
      <turnGravityOff>true</turnGravityOff-->
    <!--mu1>200</mu1>
      <mu2>200</mu2-->
    <!--selfCollide>true</selfCollide-->
    <material>Gazebo/DarkGrey</material>
  </gazebo>
  <gazebo reference="foot_left">
    <!--mu1>0.5</mu1>
      <mu2>200</mu2>
      <selfCollide>false</selfCollide>
      <turnGravityOff>true</turnGravityOff-->
    <!--selfCollide>true</selfCollide-->
    <selfCollide>false</selfCollide>
    <material>Gazebo/DarkGrey</material>
  </gazebo>
  <gazebo reference="foot_right">
    <!--mu1>0.5</mu1>
      <mu2>200</mu2>
      <selfCollide>false</selfCollide>
      <turnGravityOff>true</turnGravityOff-->
    <!--selfCollide>true</selfCollide-->
    <selfCollide>false</selfCollide>
    <material>Gazebo/DarkGrey</material>
  </gazebo>
  <gazebo reference="servo_upper_knee_left">
    <!--mu1>0.5</mu1>
      <mu2>200</mu2>
      <selfCollide>false</selfCollide>
      <turnGravityOff>true</turnGravityOff-->
    <!--mu1>200</mu1>
      <mu2>200</mu2-->
    <selfCollide>false</selfCollide>
    <material>Gazebo/DarkGrey</material>
  </gazebo>
  <gazebo reference="servo_upper_knee_right">
    <!--mu1>0.5</mu1>
      <mu2>200</mu2>
      <selfCollide>false</selfCollide>
      <turnGravityOff>true</turnGravityOff-->
    <!--mu1>200</mu1>
      <mu2>200</mu2-->
    <selfCollide>false</selfCollide>
    <material>Gazebo/DarkGrey</material>
  </gazebo>
  <gazebo reference="servo_upper_front_left">
    <!--mu1>0.5</mu1>
      <mu2>200</mu2>
      <selfCollide>false</selfCollide>
      <turnGravityOff>true</turnGravityOff-->
    <selfCollide>false</selfCollide>
    <material>Gazebo/DarkGrey</material>
  </gazebo>
  <gazebo reference="servo_upper_front_right">
    <!--mu1>0.5</mu1>
      <mu2>200</mu2>
      <selfCollide>false</selfCollide>
      <turnGravityOff>true</turnGravityOff-->
    <selfCollide>false</selfCollide>
    <material>Gazebo/DarkGrey</material>
  </gazebo>
  <gazebo reference="servo_upper_back_left">
    <!--mu1>0.5</mu1>
      <mu2>200</mu2>
      <selfCollide>false</selfCollide>
      <turnGravityOff>true</turnGravityOff-->
    <selfCollide>false</selfCollide>
    <material>Gazebo/DarkGrey</material>
  </gazebo>
  <gazebo reference="servo_upper_back_right">
    <!--mu1>0.5</mu1>
      <mu2>200</mu2>
      <selfCollide>false</selfCollide>
      <turnGravityOff>true</turnGravityOff-->
    <selfCollide>false</selfCollide>
    <material>Gazebo/DarkGrey</material>
  </gazebo>
  <gazebo reference="lower_leg_left">
    <!--mu1>0.5</mu1>
      <mu2>200</mu2>
      <selfCollide>false</selfCollide>
      <turnGravityOff>true</turnGravityOff-->
    <material>Gazebo/Red</material>
  </gazebo>
  <gazebo reference="lower_leg_right">
    <!--mu1>0.5</mu1>
      <mu2>200</mu2>
      <selfCollide>false</selfCollide>
      <turnGravityOff>true</turnGravityOff-->
    <material>Gazebo/Red</material>
  </gazebo>
  <gazebo reference="upper_leg_left">
    <!--mu1>0.5</mu1>
      <mu2>200</mu2>
      <selfCollide>false</selfCollide>
      <turnGravityOff>true</turnGravityOff-->
    <material>Gazebo/Red</material>
  </gazebo>
  <gazebo reference="upper_leg_right">
    <!--mu1>0.5</mu1>
      <mu2>200</mu2>
      <selfCollide>false</selfCollide>
      <turnGravityOff>true</turnGravityOff-->
    <material>Gazebo/Red</material>
  </gazebo>
  <gazebo reference="leg_bracket_left">
    <!--mu1>0.5</mu1>
      <mu2>200</mu2>
      <selfCollide>false</selfCollide>
      <turnGravityOff>true</turnGravityOff-->
    <material>Gazebo/Red</material>
  </gazebo>
  <gazebo reference="leg_bracket_right">
    <!--mu1>0.5</mu1>
      <mu2>200</mu2>
      <selfCollide>false</selfCollide>
      <turnGravityOff>true</turnGravityOff-->
    <material>Gazebo/Red</material>
  </gazebo>
  <gazebo reference="servo_footback_foot_left">
    <!--mu1>0.5</mu1>
      <mu2>200</mu2>
      <selfCollide>false</selfCollide>
      <turnGravityOff>true</turnGravityOff-->
    <selfCollide>false</selfCollide>
    <material>Gazebo/DarkGrey</material>
  </gazebo>
  <gazebo reference="servo_footback_foot_right">
    <!--mu1>0.5</mu1>
      <mu2>200</mu2>
      <selfCollide>false</selfCollide>
      <turnGravityOff>true</turnGravityOff-->
    <selfCollide>false</selfCollide>
    <material>Gazebo/DarkGrey</material>
  </gazebo>
  <gazebo>
    <plugin filename="libgazebo_ros_control.so" name="gazebo_ros_control">
      <robotNamespace>/raider</robotNamespace>
    </plugin>
  </gazebo>
  <transmission name="shoulder_left_swing_trans">
    <type>transmission_interface/SimpleTransmission</type>
    <joint name="shoulder_left_swing">
      <hardwareInterface>PositionJointInterface</hardwareInterface>
    </joint>
    <actuator name="shoulder_left_swing_motor">
      <hardwareInterface>PositionJointInterface</hardwareInterface>
      <mechanicalReduction>1</mechanicalReduction>
    </actuator>
  </transmission>
  <transmission name="shoulder_right_swing_trans">
    <type>transmission_interface/SimpleTransmission</type>
    <joint name="shoulder_right_swing">
      <hardwareInterface>PositionJointInterface</hardwareInterface>
    </joint>
    <actuator name="shoulder_right_swing_motor">
      <hardwareInterface>PositionJointInterface</hardwareInterface>
      <mechanicalReduction>1</mechanicalReduction>
    </actuator>
  </transmission>
  <transmission name="hip_right_swing_trans">
    <type>transmission_interface/SimpleTransmission</type>
    <joint name="hip_right_swing">
      <hardwareInterface>PositionJointInterface</hardwareInterface>
    </joint>
    <actuator name="hip_right_swing_motor">
      <hardwareInterface>PositionJointInterface</hardwareInterface>
      <mechanicalReduction>1</mechanicalReduction>
    </actuator>
  </transmission>
  <transmission name="hip_left_swing_trans">
    <type>transmission_interface/SimpleTransmission</type>
    <joint name="hip_left_swing">
      <hardwareInterface>PositionJointInterface</hardwareInterface>
    </joint>
    <actuator name="hip_left_swing_motor">
      <hardwareInterface>PositionJointInterface</hardwareInterface>
      <mechanicalReduction>1</mechanicalReduction>
    </actuator>
  </transmission>
  <transmission name="hip_right_lateral_trans">
    <type>transmission_interface/SimpleTransmission</type>
    <joint name="hip_right_lateral">
      <hardwareInterface>PositionJointInterface</hardwareInterface>
    </joint>
    <actuator name="hip_right_lateral_motor">
      <hardwareInterface>PositionJointInterface</hardwareInterface>
      <mechanicalReduction>1</mechanicalReduction>
    </actuator>
  </transmission>
  <transmission name="hip_left_lateral_trans">
    <type>transmission_interface/SimpleTransmission</type>
    <joint name="hip_left_lateral">
      <hardwareInterface>PositionJointInterface</hardwareInterface>
    </joint>
    <actuator name="hip_left_lateral_motor">
      <hardwareInterface>PositionJointInterface</hardwareInterface>
      <mechanicalReduction>1</mechanicalReduction>
    </actuator>
  </transmission>
  <transmission name="ankle_right_swing_trans">
    <type>transmission_interface/SimpleTransmission</type>
    <joint name="ankle_right_swing">
      <hardwareInterface>PositionJointInterface</hardwareInterface>
    </joint>
    <actuator name="ankle_right_swing_motor">
      <hardwareInterface>PositionJointInterface</hardwareInterface>
      <mechanicalReduction>1</mechanicalReduction>
    </actuator>
  </transmission>
  <transmission name="ankle_left_swing_trans">
    <type>transmission_interface/SimpleTransmission</type>
    <joint name="ankle_left_swing">
      <hardwareInterface>PositionJointInterface</hardwareInterface>
    </joint>
    <actuator name="ankle_left_swing_motor">
      <hardwareInterface>PositionJointInterface</hardwareInterface>
      <mechanicalReduction>1</mechanicalReduction>
    </actuator>
  </transmission>
  <transmission name="ankle_right_lateral_trans">
    <type>transmission_interface/SimpleTransmission</type>
    <joint name="ankle_right_lateral">
      <hardwareInterface>PositionJointInterface</hardwareInterface>
    </joint>
    <actuator name="ankle_right_lateral_motor">
      <hardwareInterface>PositionJointInterface</hardwareInterface>
      <mechanicalReduction>1</mechanicalReduction>
    </actuator>
  </transmission>
  <transmission name="ankle_left_lateral_trans">
    <type>transmission_interface/SimpleTransmission</type>
    <joint name="ankle_left_lateral">
      <hardwareInterface>PositionJointInterface</hardwareInterface>
    </joint>
    <actuator name="ankle_left_lateral_motor">
      <hardwareInterface>PositionJointInterface</hardwareInterface>
      <mechanicalReduction>1</mechanicalReduction>
    </actuator>
  </transmission>
  <transmission name="lower_knee_left_trans">
    <type>transmission_interface/SimpleTransmission</type>
    <joint name="lower_knee_left">
      <hardwareInterface>PositionJointInterface</hardwareInterface>
    </joint>
    <actuator name="lower_knee_left_motor">
      <hardwareInterface>PositionJointInterface</hardwareInterface>
      <mechanicalReduction>1</mechanicalReduction>
    </actuator>
  </transmission>
  <transmission name="lower_knee_right_trans">
    <type>transmission_interface/SimpleTransmission</type>
    <joint name="lower_knee_right">
      <hardwareInterface>PositionJointInterface</hardwareInterface>
    </joint>
    <actuator name="lower_knee_right_motor">
      <hardwareInterface>PositionJointInterface</hardwareInterface>
      <mechanicalReduction>1</mechanicalReduction>
    </actuator>
  </transmission>
  <transmission name="upper_knee_left_trans">
    <type>transmission_interface/SimpleTransmission</type>
    <joint name="upper_knee_left">
      <hardwareInterface>PositionJointInterface</hardwareInterface>
    </joint>
    <actuator name="upper_knee_left_motor">
      <hardwareInterface>PositionJointInterface</hardwareInterface>
      <mechanicalReduction>1</mechanicalReduction>
    </actuator>
  </transmission>
  <transmission name="upper_knee_right_trans">
    <type>transmission_interface/SimpleTransmission</type>
    <joint name="upper_knee_right">
      <hardwareInterface>PositionJointInterface</hardwareInterface>
    </joint>
    <actuator name="upper_knee_right_motor">
      <hardwareInterface>PositionJointInterface</hardwareInterface>
      <mechanicalReduction>1</mechanicalReduction>
    </actuator>
  </transmission>
  <transmission name="neck_trans">
    <type>transmission_interface/SimpleTransmission</type>
    <joint name="neck">
      <hardwareInterface>PositionJointInterface</hardwareInterface>
    </joint>
    <actuator name="neck_motor">
      <hardwareInterface>PositionJointInterface</hardwareInterface>
      <mechanicalReduction>1</mechanicalReduction>
    </actuator>
  </transmission>
  <transmission name="elbow_right_trans">
    <type>transmission_interface/SimpleTransmission</type>
    <joint name="elbow_right">
      <hardwareInterface>PositionJointInterface</hardwareInterface>
    </joint>
    <actuator name="elbow_right_motor">
      <hardwareInterface>PositionJointInterface</hardwareInterface>
      <mechanicalReduction>1</mechanicalReduction>
    </actuator>
  </transmission>
  <transmission name="elbow_left_trans">
    <type>transmission_interface/SimpleTransmission</type>
    <joint name="elbow_left">
      <hardwareInterface>PositionJointInterface</hardwareInterface>
    </joint>
    <actuator name="elbow_left_motor">
      <hardwareInterface>PositionJointInterface</hardwareInterface>
      <mechanicalReduction>1</mechanicalReduction>
    </actuator>
  </transmission>
  <transmission name="chest_trans">
    <type>transmission_interface/SimpleTransmission</type>
    <joint name="chest">
      <hardwareInterface>PositionJointInterface</hardwareInterface>
    </joint>
    <actuator name="chest_motor">
      <hardwareInterface>PositionJointInterface</hardwareInterface>
      <mechanicalReduction>1</mechanicalReduction>
    </actuator>
  </transmission>
  <transmission name="groin_right_trans">
    <type>transmission_interface/SimpleTransmission</type>
    <joint name="groin_right">
      <hardwareInterface>PositionJointInterface</hardwareInterface>
    </joint>
    <actuator name="groin_right_motor">
      <hardwareInterface>PositionJointInterface</hardwareInterface>
      <mechanicalReduction>1</mechanicalReduction>
    </actuator>
  </transmission>
  <transmission name="groin_left_trans">
    <type>transmission_interface/SimpleTransmission</type>
    <joint name="groin_left">
      <hardwareInterface>PositionJointInterface</hardwareInterface>
    </joint>
    <actuator name="groin_left_motor">
      <hardwareInterface>PositionJointInterface</hardwareInterface>
      <mechanicalReduction>1</mechanicalReduction>
    </actuator>
  </transmission>
  <transmission name="shoulder_right_lateral_trans">
    <type>transmission_interface/SimpleTransmission</type>
    <joint name="shoulder_right_lateral">
      <hardwareInterface>PositionJointInterface</hardwareInterface>
    </joint>
    <actuator name="shoulder_right_lateral_motor">
      <hardwareInterface>PositionJointInterface</hardwareInterface>
      <mechanicalReduction>1</mechanicalReduction>
    </actuator>
  </transmission>
  <transmission name="shoulder_left_lateral_trans">
    <type>transmission_interface/SimpleTransmission</type>
    <joint name="shoulder_left_lateral">
      <hardwareInterface>PositionJointInterface</hardwareInterface>
    </joint>
    <actuator name="shoulder_left_lateral_motor">
      <hardwareInterface>PositionJointInterface</hardwareInterface>
      <mechanicalReduction>1</mechanicalReduction>
    </actuator>
  </transmission>
  <material name="black">
    <color rgba="1.0 1.0 1.0 1.0"/>
  </material>
  <material name="blue">
    <color rgba="0.0 0.0 0.8 1.0"/>
  </material>
  <material name="green">
    <color rgba="0 102 0 1.0"/>
  </material>
  <material name="grey">
    <color rgba="0.2 0.2 0.2 1.0"/>
  </material>
  <material name="orange">
    <color rgba="1.0 0.423529411765 0.0392156862745 1.0"/>
  </material>
  <material name="brown">
    <color rgba="0.870588235294 0.811764705882 0.764705882353 1.0"/>
  </material>
  <material name="red">
    <color rgba="0.8 0.0 0.0 1.0"/>
  </material>
  <material name="white">
    <color rgba="1.0 1.0 1.0 1.0"/>
  </material>
  <link name="base_link"/>
  <joint name="base_joint_left" type="fixed">
    <parent link="base_link"/>
    <child link="hip_chassis"/>
    <origin xyz="0 0 0"/>
  </joint>
  <joint name="chest" type="revolute">
    <dynamics damping="0.0" friction="0.0"/>
    <limit effort="100" lower="-3.14159265359" upper="3.14159265359" velocity="3"/>
    <parent link="upper_hip"/>
    <child link="chest_chassis"/>
    <origin xyz="0 0 76.94e-3"/>
    <!--origin xyz="0 0 76.94e-3"/-->
    <axis xyz="0 0 1"/>
  </joint>
  <link name="upper_hip">
    <collision>
      <origin rpy="0 0 0" xyz="0 0 0"/>
      <geometry>
        <mesh filename="package://raider_description/meshes/hip/upper_hip.dae" scale="0.001 0.001 0.001"/>
      </geometry>
    </collision>
    <visual>
      <origin rpy="0 0 0" xyz="0 0 0"/>
      <geometry>
        <mesh filename="package://raider_description/meshes/hip/upper_hip.dae" scale="0.001 0.001 0.001"/>
      </geometry>
    </visual>
    <inertial>
      <origin rpy="0 0 0" xyz="0.000005e-3 -6.968965e-3 74.913368e-3"/>
      <mass value="5e-3"/>
      <inertia ixx="1.477029903" ixy="-0.000000099" ixz="0.000000796" iyy="1.164759175" iyz="-0.00047014" izz="2.628691944"/>
    </inertial>
  </link>
  <joint name="servo_upperhip_middle" type="fixed">
    <parent link="servo_hip_middle"/>
    <child link="upper_hip"/>
    <origin xyz="0 0 0"/>
  </joint>
  <link name="servo_hip_middle">
    <collision>
      <origin rpy="0 0 0" xyz="0 0 0"/>
      <geometry>
        <mesh filename="package://raider_description/meshes/hip/servo_hip_middle.dae" scale="0.001 0.001 0.001"/>
      </geometry>
    </collision>
    <visual>
      <origin rpy="0 0 0" xyz="0 0 0"/>
      <geometry>
        <mesh filename="package://raider_description/meshes/hip/servo_hip_middle.dae" scale="0.001 0.001 0.001"/>
      </geometry>
    </visual>
    <inertial>
      <origin rpy="0 0 0" xyz="-0.002708e-3 -12.799425e-3 57.999710e-3"/>
      <mass value="0.055"/>
      <inertia ixx="15.8415211027" ixy="-0.00118068325002" ixz="0.0025727810005" iyy="8.7314675513" iyz="-0.117183116359" izz="13.3726293836"/>
    </inertial>
  </link>
  <joint name="servo_hipchassis_middle" type="fixed">
    <parent link="hip_chassis"/>
    <child link="servo_hip_middle"/>
    <origin xyz="0 0 0"/>
  </joint>
  <link name="hip_chassis">
    <collision>
      <origin rpy="0 0 0" xyz="0 0 0"/>
      <geometry>
        <mesh filename="package://raider_description/meshes/hip/hip_chassis.dae" scale="0.001 0.001 0.001"/>
      </geometry>
    </collision>
    <visual>
      <origin rpy="0 0 0" xyz="0 0 0"/>
      <geometry>
        <mesh filename="package://raider_description/meshes/hip/hip_chassis.dae" scale="0.001 0.001 0.001"/>
      </geometry>
    </visual>
    <inertial>
      <origin rpy="0 0 0" xyz="0 8.793029e-3 50.608299e-3"/>
      <mass value="16e-3"/>
      <inertia ixx="5.191173851" ixy="0.000000575" ixz="-0.000000273" iyy="4.106148647" iyz="-1.012029816" izz="5.375464492"/>
    </inertial>
  </link>
  <joint name="hip_right_lateral" type="revolute">
    <dynamics damping="0.0" friction="0.0"/>
    <limit effort="100" lower="-3.14159265359" upper="3.14159265359" velocity="3"/>
    <parent link="servo_hip_right"/>
    <child link="leg_bracket_right"/>
    <origin xyz="32e-3 -21e-3 31e-3"/>
    <axis xyz="0 0 1"/>
  </joint>
  <joint name="servo_middle_right" type="fixed">
    <parent link="servo_hip_middle"/>
    <child link="servo_hip_right"/>
    <origin xyz="0 0 0"/>
  </joint>
  <joint name="servo_middle_left" type="fixed">
    <parent link="servo_hip_middle"/>
    <child link="servo_hip_left"/>
    <origin xyz="0 0 0"/>
  </joint>
  <link name="servo_hip_left">
    <collision>
      <origin rpy="0 0 0" xyz="0 0 0"/>
      <geometry>
        <mesh filename="package://raider_description/meshes/hip/servo_hip_left.dae" scale="0.001 0.001 0.001"/>
      </geometry>
    </collision>
    <visual>
      <origin rpy="0 0 0" xyz="0 0 0"/>
      <geometry>
        <mesh filename="package://raider_description/meshes/hip/servo_hip_left.dae" scale="0.001 0.001 0.001"/>
      </geometry>
    </visual>
    <inertial>
      <origin rpy="0 0 0" xyz="-32.002708e-3 -8.200576e-3 55.880287e-3"/>
      <mass value="0.055"/>
      <inertia ixx="15.8415224174" ixy="0.00118074969079" ixz="-0.00257299316212" iyy="8.73146886599" iyz="-0.117182962293" izz="13.3726293836"/>
    </inertial>
  </link>
  <joint name="hip_left_lateral" type="revolute">
    <dynamics damping="0.0" friction="0.0"/>
    <limit effort="100" lower="-3.14159265359" upper="3.14159265359" velocity="3"/>
    <parent link="servo_hip_left"/>
    <child link="leg_bracket_left"/>
    <origin rpy="0 3.14159265359 0" xyz="-32e-3 -21e-3 31e-3"/>
    <axis xyz="0 0 1"/>
  </joint>
  <link name="servo_hip_right">
    <collision>
      <origin rpy="0 0 0" xyz="0 0 0"/>
      <geometry>
        <mesh filename="package://raider_description/meshes/hip/servo_hip_right.dae" scale="0.001 0.001 0.001"/>
      </geometry>
    </collision>
    <visual>
      <origin rpy="0 0 0" xyz="0 0 0"/>
      <geometry>
        <mesh filename="package://raider_description/meshes/hip/servo_hip_right.dae" scale="0.001 0.001 0.001"/>
      </geometry>
    </visual>
    <inertial>
      <origin rpy="0 0 0" xyz="31.997292e-3 -8.200576e-3 55.880287e-3"/>
      <mass value="0.055"/>
      <inertia ixx="15.8414921794" ixy="0.00118071582817" ixz="-0.0025727784329" iyy="8.73143008247" iyz="-0.117182274131" izz="13.3726293836"/>
    </inertial>
  </link>
  <joint name="ankle_left_lateral" type="revolute">
    <dynamics damping="0.0" friction="0.0"/>
    <limit effort="100" lower="-1.57079632679" upper="1.57079632679" velocity="3"/>
    <parent link="back_ankle_left"/>
    <child link="foot_left"/>
    <origin rpy="0 0 0.0" xyz="0.025 0 -1.25e-3"/>
    <axis xyz="0 1 0"/>
  </joint>
  <link name="foot_left">
    <collision>
      <origin rpy="0 0 0" xyz="0.032 4.06e-3 173e-3"/>
      <geometry>
        <mesh filename="package://raider_description/meshes/leg_left/foot_left.dae" scale="0.001 0.001 0.001"/>
      </geometry>
    </collision>
    <visual>
      <origin rpy="0 0 0" xyz="0.032 4.06e-3 173e-3"/>
      <geometry>
        <mesh filename="package://raider_description/meshes/leg_left/foot_left.dae" scale="0.001 0.001 0.001"/>
      </geometry>
    </visual>
    <inertial>
      <origin rpy="0 0 0" xyz="-0.034218262 -2.616092e-3 -194.773895e-3"/>
      <mass value="31e-3"/>
      <inertia ixx="22.27440675" ixy="0.003825417" ixz="-0.290640621" iyy="8.364372176" iyz="0.190691357" izz="26.713433444"/>
    </inertial>
  </link>
  <joint name="frontankle_servofoot_left" type="fixed">
    <parent link="servo_foot_left"/>
    <child link="front_ankle_left"/>
    <origin xyz="0 0 0"/>
  </joint>
  <link name="front_ankle_left">
    <collision>
      <origin rpy="0 0 0" xyz="0.05694 4.06e-3 171.75e-3"/>
      <geometry>
        <mesh filename="package://raider_description/meshes/leg_left/front_ankle_left.dae" scale="0.001 0.001 0.001"/>
      </geometry>
    </collision>
    <visual>
      <origin rpy="0 0 0" xyz="0.05694 4.06e-3 171.75e-3"/>
      <geometry>
        <mesh filename="package://raider_description/meshes/leg_left/front_ankle_left.dae" scale="0.001 0.001 0.001"/>
      </geometry>
    </visual>
    <inertial>
      <origin rpy="0 0 0" xyz="-32.000015 11.489568e-3 -158.031693e-3"/>
      <mass value="7e-3"/>
      <inertia ixx="0.998184643" ixy="-9.8e-07" ixz="-4.71e-07" iyy="1.627441646" iyz="0.005153015" izz="0.66988573"/>
    </inertial>
  </link>
  <link name="servo_foot_left">
    <collision>
      <origin rpy="0 0 0" xyz="0.05694 4.06e-3 171.75e-3"/>
      <geometry>
        <mesh filename="package://raider_description/meshes/leg_left/servo_foot_left.dae" scale="0.001 0.001 0.001"/>
      </geometry>
    </collision>
    <visual>
      <origin rpy="0 0 0" xyz="0.05694 4.06e-3 171.75e-3"/>
      <geometry>
        <mesh filename="package://raider_description/meshes/leg_left/servo_foot_left.dae" scale="0.001 0.001 0.001"/>
      </geometry>
    </visual>
    <inertial>
      <origin rpy="0 0 0" xyz="-0.033059711 -4.057295e-3 -160.200577e-3"/>
      <mass value="0.055"/>
      <inertia ixx="13.364814134" ixy="0.00257095312562" ixz="-0.11423344641" iyy="15.8322543731" iyz="-0.00117736011226" izz="8.72746505169"/>
    </inertial>
  </link>
  <joint name="joint_servo_backankle_left" type="fixed">
    <origin xyz="0 0 0"/>
    <parent link="servo_foot_left"/>
    <child link="back_ankle_left"/>
  </joint>
  <link name="back_ankle_left">
    <collision>
      <origin rpy="0 0 0" xyz="0.05694 4.06e-3 171.75e-3"/>
      <geometry>
        <mesh filename="package://raider_description/meshes/leg_left/back_ankle_left.dae" scale="0.001 0.001 0.001"/>
      </geometry>
    </collision>
    <visual>
      <origin rpy="0 0 0" xyz="0.05694 4.06e-3 171.75e-3"/>
      <geometry>
        <mesh filename="package://raider_description/meshes/leg_left/back_ankle_left.dae" scale="0.001 0.001 0.001"/>
      </geometry>
    </visual>
    <inertial>
      <origin rpy="0 0 0" xyz="-0.032000099 -25.044254e-3 -149.531372e-3"/>
      <mass value="5e-3"/>
      <inertia ixx="0.409812725" ixy="5.505e-06" ixz="-1.444e-06" iyy="1.2913425" iyz="0.013904179" izz="1.050779904"/>
    </inertial>
  </link>
  <joint name="servo_footback_foot_left" type="fixed">
    <parent link="back_ankle_left"/>
    <child link="servo_footback_left"/>
    <origin xyz="0 0 0"/>
  </joint>
  <link name="servo_footback_left">
    <collision>
      <origin rpy="0 0 0" xyz="0.05694 4.06e-3 171.75e-3"/>
      <geometry>
        <mesh filename="package://raider_description/meshes/leg_left/servo_footback_left.dae" scale="0.001 0.001 0.001"/>
      </geometry>
    </collision>
    <visual>
      <origin rpy="0 0 0" xyz="0.05694 4.06e-3 171.75e-3"/>
      <geometry>
        <mesh filename="package://raider_description/meshes/leg_left/servo_footback_left.dae" scale="0.001 0.001 0.001"/>
      </geometry>
    </visual>
    <inertial>
      <origin rpy="0 0 0" xyz="-0.031997292 -44.940292e-3 -160.200577e-3"/>
      <mass value="0.055"/>
      <inertia ixx="15.8507050963" ixy="-0.00257508129933" ixz="-0.00118342639725" iyy="13.3805905153" iyz="0.117258473054" izz="8.73655952446"/>
    </inertial>
  </link>
  <joint name="ankle_left_swing" type="revolute">
    <dynamics damping="0.0" friction="0.0"/>
    <limit effort="100" lower="-1" upper="1" velocity="3"/>
    <origin rpy="0 0 0" xyz="0 0 -75e-3"/>
    <parent link="lower_leg_left"/>
    <child link="servo_foot_left"/>
    <axis xyz="1 0 0"/>
  </joint>
  <link name="lower_leg_left">
    <collision>
      <origin rpy="0 0 0" xyz="0.05694 4.06e-3 96.75e-3"/>
      <geometry>
        <mesh filename="package://raider_description/meshes/leg_left/lower_leg_left.dae" scale="0.001 0.001 0.001"/>
      </geometry>
    </collision>
    <visual>
      <origin rpy="0 0 0" xyz="0.05694 4.06e-3 96.75e-3"/>
      <geometry>
        <mesh filename="package://raider_description/meshes/leg_left/lower_leg_left.dae" scale="0.001 0.001 0.001"/>
      </geometry>
    </visual>
    <inertial>
      <origin rpy="0 0 0" xyz="-0.0336647 9.614051e-3 -125.379684e-3"/>
      <mass value="44e-3"/>
      <inertia ixx="40.466879268" ixy="-0.767591492" ixz="-0.904685905" iyy="49.378616404" iyz="-3.268945377" izz="24.910608508"/>
    </inertial>
  </link>
  <joint name="lower_knee_left" type="revolute">
    <dynamics damping="0.0" friction="0.0"/>
    <limit effort="100" lower="-1.57079632679" upper="1.57079632679" velocity="3"/>
    <origin rpy="0 0 0" xyz="0 0 -32e-3"/>
    <parent link="servo_lower_knee_left"/>
    <child link="lower_leg_left"/>
    <axis xyz="1 0 0"/>
  </joint>
  <link name="servo_lower_knee_left">
    <collision>
      <origin rpy="0 0 0" xyz="0.05694 4.06e-3 64.75e-3"/>
      <geometry>
        <mesh filename="package://raider_description/meshes/leg_left/servo_lower_knee_left.dae" scale="0.001 0.001 0.001"/>
      </geometry>
    </collision>
    <visual>
      <origin rpy="0 0 0" xyz="0.05694 4.06e-3 64.75e-3"/>
      <geometry>
        <mesh filename="package://raider_description/meshes/leg_left/servo_lower_knee_left.dae" scale="0.001 0.001 0.001"/>
      </geometry>
    </visual>
    <inertial>
      <origin rpy="0 0 0" xyz="-0.033059711 -16.859426e-3 -97.997299e-3"/>
      <mass value="0.055"/>
      <inertia ixx="13.3648128854" ixy="0.11423240803" ixz="0.00257091338332" iyy="8.72746489408" iyz="0.0011773616887" izz="15.8322542094"/>
    </inertial>
  </link>
  <joint name="joint_servolowerknee_kneedamper1_left" type="fixed">
    <origin xyz="0 0 0"/>
    <parent link="knee_damper_1_left"/>
    <child link="servo_lower_knee_left"/>
  </joint>
  <link name="knee_damper_1_left">
    <collision>
      <origin rpy="0 0 0" xyz="0.05694 4.06e-3 64.75e-3"/>
      <geometry>
        <mesh filename="package://raider_description/meshes/leg_left/knee_damperleft_1.dae" scale="0.001 0.001 0.001"/>
      </geometry>
    </collision>
    <visual>
      <origin rpy="0 0 0" xyz="0.05694 4.06e-3 64.75e-3"/>
      <geometry>
        <mesh filename="package://raider_description/meshes/leg_left/knee_damperleft_1.dae" scale="0.001 0.001 0.001"/>
      </geometry>
    </visual>
    <inertial>
      <origin rpy="0 0 0" xyz="-0.049524082 -31.720390e-3 -78.538048e-3"/>
      <mass value="2e-3"/>
      <inertia ixx="0.423026673" ixy="-0.007535722" ixz="0.00201741" iyy="0.136987356" iyz="0.067385341" izz="0.290494473"/>
    </inertial>
  </link>
  <link name="knee_damper_2_left">
    <collision>
      <origin rpy="0 0 0" xyz="0.05694 4.06e-3 64.75e-3"/>
      <geometry>
        <mesh filename="package://raider_description/meshes/leg_left/knee_damperleft_2.dae" scale="0.001 0.001 0.001"/>
      </geometry>
    </collision>
    <visual>
      <origin rpy="0 0 0" xyz="0.05694 4.06e-3 64.75e-3"/>
      <geometry>
        <mesh filename="package://raider_description/meshes/leg_left/knee_damperleft_2.dae" scale="0.001 0.001 0.001"/>
      </geometry>
    </visual>
    <inertial>
      <origin rpy="0 0 0" xyz="-0.014675918 -31.720392e-3 -78.538040e-3"/>
      <mass value="2e-3"/>
      <inertia ixx="0.423026894489" ixy="0.00753540714801" ixz="-0.00201733869804" iyy="0.13698782028" iyz="0.0673854098023" izz="0.290494829316"/>
    </inertial>
  </link>
  <joint name="joint_damper2leg_servoupperknee_left" type="fixed">
    <origin xyz="0 0 0"/>
    <parent link="servo_upper_knee_left"/>
    <child link="knee_damper_2_left"/>
  </joint>
  <joint name="joint_damper1leg_servoupperknee_left" type="fixed">
    <origin xyz="0 0 0"/>
    <parent link="servo_upper_knee_left"/>
    <child link="knee_damper_1_left"/>
  </joint>
  <link name="servo_upper_knee_left">
    <collision>
      <origin rpy="0 0 0" xyz="0.05694 4.06e-3 64.75e-3"/>
      <geometry>
        <mesh filename="package://raider_description/meshes/leg_left/servo_upperleft_knee.dae" scale="0.001 0.001 0.001"/>
      </geometry>
    </collision>
    <visual>
      <origin rpy="0 0 0" xyz="0.05694 4.06e-3 64.75e-3"/>
      <geometry>
        <mesh filename="package://raider_description/meshes/leg_left/servo_upperleft_knee.dae" scale="0.001 0.001 0.001"/>
      </geometry>
    </visual>
    <inertial>
      <origin rpy="0 0 0" xyz="-0.033059711 -16.859426e-3 -65.997299e-3"/>
      <mass value="0.055"/>
      <inertia ixx="13.3726780935" ixy="0.117182581594" ixz="0.00257237409081" iyy="8.73145293176" iyz="0.00118132163081" izz="15.8415064767"/>
    </inertial>
  </link>
  <joint name="upper_knee_left" type="revolute">
    <dynamics damping="0.0" friction="0.0"/>
    <origin rpy="0 0 0" xyz="0 0 -73.75e-3"/>
    <limit effort="100" lower="-1.57079632679" upper="1.57079632679" velocity="3"/>
    <parent link="upper_leg_left"/>
    <child link="servo_upper_knee_left"/>
  </joint>
  <link name="upper_leg_left">
    <collision>
      <origin rpy="0 0 0" xyz="0.05694 4.06e-3 -9e-3"/>
      <geometry>
        <mesh filename="package://raider_description/meshes/leg_left/upper_leg_left.dae" scale="0.001 0.001 0.001"/>
      </geometry>
    </collision>
    <visual>
      <origin rpy="0 0 0" xyz="0.05694 4.06e-3 -9e-3"/>
      <geometry>
        <mesh filename="package://raider_description/meshes/leg_left/upper_leg_left.dae" scale="0.001 0.001 0.001"/>
      </geometry>
    </visual>
    <inertial>
      <origin rpy="0 0 0" xyz="-0.033380638 -0.118964e-3 -33.265591e-3"/>
      <mass value="23e-3"/>
      <inertia ixx="16.287494127" ixy="-0.039940722" ixz="0.048285696" iyy="24.786351073" iyz="1.256185001" izz="12.170186251"/>
    </inertial>
  </link>
  <joint name="hip_left_swing" type="revolute">
    <dynamics damping="0.0" friction="0.0"/>
    <limit effort="100" lower="-1.57079632679" upper="1.57079632679" velocity="3"/>
    <origin rpy="0 0 0" xyz="-0.02494 56.94e-3 0"/>
    <parent link="servo_upper_front_left"/>
    <child link="upper_leg_left"/>
  </joint>
  <link name="servo_upper_front_left">
    <collision>
      <origin rpy="0 0 0" xyz="0.032 61e-3 -9e-3"/>
      <geometry>
        <mesh filename="package://raider_description/meshes/leg_left/servo_upperleft_front.dae" scale="0.001 0.001 0.001"/>
      </geometry>
    </collision>
    <visual>
      <origin rpy="0 0 0" xyz="0.032 61e-3 -9e-3"/>
      <geometry>
        <mesh filename="package://raider_description/meshes/leg_left/servo_upperleft_front.dae" scale="0.001 0.001 0.001"/>
      </geometry>
    </visual>
    <inertial>
      <origin rpy="0 0 0" xyz="-0.033259712 -4.062710e-3 -3.799430e-3"/>
      <mass value="0.055"/>
      <inertia ixx="13.3648128854" ixy="-0.000243300048112" ixz="0.114233548786" iyy="15.832252894" iyz="-0.00117736473926" izz="8.72746489408"/>
    </inertial>
  </link>
  <joint name="joint_servoupperfront_tobleft" type="fixed">
    <origin xyz="0 0 0"/>
    <parent link="servo_upper_front_left"/>
    <child link="tob_left"/>
  </joint>
  <link name="tob_left">
    <collision>
      <origin rpy="0 0 0" xyz="0.032 61e-3 -9e-3"/>
      <geometry>
        <mesh filename="package://raider_description/meshes/leg_left/tob_left.dae" scale="0.001 0.001 0.001"/>
      </geometry>
    </collision>
    <visual>
      <origin rpy="0 0 0" xyz="0.032 61e-3 -9e-3"/>
      <geometry>
        <mesh filename="package://raider_description/meshes/leg_left/tob_left.dae" scale="0.001 0.001 0.001"/>
      </geometry>
    </visual>
    <inertial>
      <origin rpy="0 0 0" xyz="-0.031999987 12.549569e-3 -5.968293e-3"/>
      <mass value="7e-3"/>
      <inertia ixx="0.998184661" ixy="1.004e-06" ixz="-1.021e-06" iyy="1.627441646" iyz="-0.005152814" izz="0.669885346"/>
    </inertial>
  </link>
  <joint name="jointleft_servoupperfront_groin2" type="fixed">
    <origin xyz="0 0 0"/>
    <parent link="groin2_left"/>
    <child link="servo_upper_front_left"/>
  </joint>
  <link name="groin2_left">
    <collision>
      <origin rpy="0 0 0" xyz="0.032 61e-3 -9e-3"/>
      <geometry>
        <mesh filename="package://raider_description/meshes/leg_left/groin2_left.dae" scale="0.001 0.001 0.001"/>
      </geometry>
    </collision>
    <visual>
      <origin rpy="0 0 0" xyz="0.032 61e-3 -9e-3"/>
      <geometry>
        <mesh filename="package://raider_description/meshes/leg_left/groin2_left.dae" scale="0.001 0.001 0.001"/>
      </geometry>
    </visual>
    <inertial>
      <origin rpy="0 0 0" xyz="-0.016159353 -35.801258e-3 -7.292182e-3"/>
      <mass value="5e-3"/>
      <inertia ixx="0.964450567" ixy="0.032521998" ixz="-0.003002097" iyy="0.377541101" iyz="0.088795829" izz="0.612968817"/>
    </inertial>
  </link>
  <joint name="jointleft_servoupperback_groin1" type="fixed">
    <origin rpy="0 0 0.0" xyz="0 0.0 0"/>
    <parent link="servo_upper_back_left"/>
    <child link="groin2_left"/>
  </joint>
  <link name="groin1_left">
    <collision>
      <origin rpy="0 0 0" xyz="0.032 61e-3 -9e-3"/>
      <geometry>
        <mesh filename="package://raider_description/meshes/leg_left/groin1_left.dae" scale="0.001 0.001 0.001"/>
      </geometry>
    </collision>
    <visual>
      <origin rpy="0 0 0" xyz="0.032 61e-3 -9e-3"/>
      <geometry>
        <mesh filename="package://raider_description/meshes/leg_left/groin1_left.dae" scale="0.001 0.001 0.001"/>
      </geometry>
    </visual>
    <inertial>
      <origin rpy="0 0 0" xyz="-0.047840645 -35.801262e-3 -7.292187e-3"/>
      <mass value="5e-3"/>
      <inertia ixx="0.964451283" ixy="-0.032521697" ixz="0.003002165" iyy="0.377541141" iyz="0.08879578" izz="0.612969334"/>
    </inertial>
  </link>
  <joint name="joint_servoupperback_groin1_left" type="fixed">
    <origin rpy="0 0 0.0" xyz="0 0.0 0"/>
    <parent link="servo_upper_back_left"/>
    <child link="groin1_left"/>
  </joint>
  <link name="servo_upper_back_left">
    <collision>
      <origin rpy="0 0 0" xyz="0.032 61e-3 -9e-3"/>
      <geometry>
        <mesh filename="package://raider_description/meshes/leg_left/servo_upperleft_back.dae" scale="0.001 0.001 0.001"/>
      </geometry>
    </collision>
    <visual>
      <origin rpy="0 0 0" xyz="0.032 61e-3 -9e-3"/>
      <geometry>
        <mesh filename="package://raider_description/meshes/leg_left/servo_upperleft_back.dae" scale="0.001 0.001 0.001"/>
      </geometry>
    </visual>
    <inertial>
      <origin rpy="0 0 0" xyz="-0.031997288 -37.115585e-3 -3.810416e-3"/>
      <mass value="0.055"/>
      <inertia ixx="15.832250263" ixy="0.000243300047342" ixz="0.00117736064422" iyy="13.3648128854" iyz="0.114233158256" izz="8.72746818275"/>
    </inertial>
  </link>
  <joint name="groin_left" type="revolute">
    <limit effort="100" lower="-1.57079632679" upper="1.57079632679" velocity="3"/>
    <origin rpy="0 -3.14159265359 0.0" xyz="0 -0.04 0.022"/>
    <parent link="leg_bracket_left"/>
    <child link="servo_upper_back_left"/>
    <axis xyz="0 1 0"/>
  </joint>
  <link name="leg_bracket_left">
    <collision>
      <origin rpy="0 0 0" xyz="0.032 21e-3 -31e-3"/>
      <geometry>
        <mesh filename="package://raider_description/meshes/leg_left/leg_bracket_left.dae" scale="0.001 0.001 0.001"/>
      </geometry>
    </collision>
    <visual>
      <origin rpy="0 0 0" xyz="0.032 21e-3 -31e-3"/>
      <geometry>
        <mesh filename="package://raider_description/meshes/leg_left/leg_bracket_left.dae" scale="0.001 0.001 0.001"/>
      </geometry>
    </visual>
    <inertial>
      <origin rpy="0 0 0" xyz="-0.031468872 -22.709967e-3 27.662817e-3"/>
      <mass value="17e-3"/>
      <inertia ixx="14.953408409" ixy="-0.236958746" ixz="-0.081847589" iyy="0.281864658" iyz="-0.318501245" izz="14.972208875"/>
    </inertial>
  </link>
  <joint name="ankle_right_lateral" type="revolute">
    <dynamics damping="0.0" friction="0.0"/>
    <limit effort="100" lower="-1.57079632679" upper="1.57079632679" velocity="3"/>
    <parent link="back_ankle_right"/>
    <child link="foot_right"/>
    <origin rpy="0 0 3.14159265359" xyz="-0.025 0 -1.25e-3"/>
    <axis xyz="0 1 0"/>
  </joint>
  <link name="foot_right">
    <collision>
      <origin rpy="0 0 0" xyz="-0.032 4.06e-3 173e-3"/>
      <geometry>
        <mesh filename="package://raider_description/meshes/leg_right/foot_right.dae" scale="0.001 0.001 0.001"/>
      </geometry>
    </collision>
    <visual>
      <origin rpy="0 0 0" xyz="-0.032 4.06e-3 173e-3"/>
      <geometry>
        <mesh filename="package://raider_description/meshes/leg_right/foot_right.dae" scale="0.001 0.001 0.001"/>
      </geometry>
    </visual>
    <inertial>
      <origin rpy="0 0 0" xyz="0.034218262 -2.616092e-3 -194.773895e-3"/>
      <mass value="31e-3"/>
      <inertia ixx="22.27440675" ixy="-0.003825417" ixz="0.290640621" iyy="8.364372176" iyz="0.190691357" izz="26.713433444"/>
    </inertial>
  </link>
  <joint name="frontankle_servofoot_right" type="fixed">
    <parent link="servo_foot_right"/>
    <child link="front_ankle_right"/>
    <origin xyz="0 0 0"/>
  </joint>
  <link name="front_ankle_right">
    <collision>
      <origin rpy="0 0 0" xyz="-0.05694 4.06e-3 171.75e-3"/>
      <geometry>
        <mesh filename="package://raider_description/meshes/leg_right/front_ankle_right.dae" scale="0.001 0.001 0.001"/>
      </geometry>
    </collision>
    <visual>
      <origin rpy="0 0 0" xyz="-0.05694 4.06e-3 171.75e-3"/>
      <geometry>
        <mesh filename="package://raider_description/meshes/leg_right/front_ankle_right.dae" scale="0.001 0.001 0.001"/>
      </geometry>
    </visual>
    <inertial>
      <origin rpy="0 0 0" xyz="32.000015 11.489568e-3 -158.031693e-3"/>
      <mass value="7e-3"/>
      <inertia ixx="0.998184643" ixy="9.8e-07" ixz="4.71e-07" iyy="1.627441646" iyz="0.005153015" izz="0.66988573"/>
    </inertial>
  </link>
  <link name="servo_foot_right">
    <collision>
      <origin rpy="0 0 0" xyz="-0.05694 4.06e-3 171.75e-3"/>
      <geometry>
        <mesh filename="package://raider_description/meshes/leg_right/servo_foot_right.dae" scale="0.001 0.001 0.001"/>
      </geometry>
    </collision>
    <visual>
      <origin rpy="0 0 0" xyz="-0.05694 4.06e-3 171.75e-3"/>
      <geometry>
        <mesh filename="package://raider_description/meshes/leg_right/servo_foot_right.dae" scale="0.001 0.001 0.001"/>
      </geometry>
    </visual>
    <inertial>
      <origin rpy="0 0 0" xyz="0.033059711 -4.057295e-3 -160.200577e-3"/>
      <mass value="0.055"/>
      <inertia ixx="13.364814134" ixy="-0.00257095312562" ixz="0.11423344641" iyy="15.8322543731" iyz="-0.00117736011226" izz="8.72746505169"/>
    </inertial>
  </link>
  <joint name="joint_servo_backankle_right" type="fixed">
    <origin xyz="0 0 0"/>
    <parent link="servo_foot_right"/>
    <child link="back_ankle_right"/>
  </joint>
  <link name="back_ankle_right">
    <collision>
      <origin rpy="0 0 0" xyz="-0.05694 4.06e-3 171.75e-3"/>
      <geometry>
        <mesh filename="package://raider_description/meshes/leg_right/back_ankle_right.dae" scale="0.001 0.001 0.001"/>
      </geometry>
    </collision>
    <visual>
      <origin rpy="0 0 0" xyz="-0.05694 4.06e-3 171.75e-3"/>
      <geometry>
        <mesh filename="package://raider_description/meshes/leg_right/back_ankle_right.dae" scale="0.001 0.001 0.001"/>
      </geometry>
    </visual>
    <inertial>
      <origin rpy="0 0 0" xyz="0.032000099 -25.044254e-3 -149.531372e-3"/>
      <mass value="5e-3"/>
      <inertia ixx="0.409812725" ixy="-5.505e-06" ixz="1.444e-06" iyy="1.2913425" iyz="0.013904179" izz="1.050779904"/>
    </inertial>
  </link>
  <joint name="servo_footback_foot_right" type="fixed">
    <parent link="back_ankle_right"/>
    <child link="servo_footback_right"/>
    <origin xyz="0 0 0"/>
  </joint>
  <link name="servo_footback_right">
    <collision>
      <origin rpy="0 0 0" xyz="-0.05694 4.06e-3 171.75e-3"/>
      <geometry>
        <mesh filename="package://raider_description/meshes/leg_right/servo_footback_right.dae" scale="0.001 0.001 0.001"/>
      </geometry>
    </collision>
    <visual>
      <origin rpy="0 0 0" xyz="-0.05694 4.06e-3 171.75e-3"/>
      <geometry>
        <mesh filename="package://raider_description/meshes/leg_right/servo_footback_right.dae" scale="0.001 0.001 0.001"/>
      </geometry>
    </visual>
    <inertial>
      <origin rpy="0 0 0" xyz="0.031997292 -44.940292e-3 -160.200577e-3"/>
      <mass value="0.055"/>
      <inertia ixx="15.8507050963" ixy="0.00257508129933" ixz="0.00118342639725" iyy="13.3805905153" iyz="0.117258473054" izz="8.73655952446"/>
    </inertial>
  </link>
  <joint name="ankle_right_swing" type="revolute">
    <dynamics damping="0.0" friction="0.0"/>
    <limit effort="100" lower="-1" upper="1" velocity="3"/>
    <origin rpy="0 0 0" xyz="0 0 -75e-3"/>
    <parent link="lower_leg_right"/>
    <child link="servo_foot_right"/>
    <axis xyz="1 0 0"/>
  </joint>
  <link name="lower_leg_right">
    <collision>
      <origin rpy="0 0 0" xyz="-0.05694 4.06e-3 96.75e-3"/>
      <geometry>
        <mesh filename="package://raider_description/meshes/leg_right/lower_leg_right.dae" scale="0.001 0.001 0.001"/>
      </geometry>
    </collision>
    <visual>
      <origin rpy="0 0 0" xyz="-0.05694 4.06e-3 96.75e-3"/>
      <geometry>
        <mesh filename="package://raider_description/meshes/leg_right/lower_leg_right.dae" scale="0.001 0.001 0.001"/>
      </geometry>
    </visual>
    <inertial>
      <origin rpy="0 0 0" xyz="0.0336647 9.614051e-3 -125.379684e-3"/>
      <mass value="44e-3"/>
      <inertia ixx="40.466879268" ixy="0.767591492" ixz="0.904685905" iyy="49.378616404" iyz="-3.268945377" izz="24.910608508"/>
    </inertial>
  </link>
  <joint name="lower_knee_right" type="revolute">
    <dynamics damping="0.0" friction="0.0"/>
    <limit effort="100" lower="-1.57079632679" upper="1.57079632679" velocity="3"/>
    <origin rpy="0 0 0" xyz="0 0 -32e-3"/>
    <parent link="servo_lower_knee_right"/>
    <child link="lower_leg_right"/>
    <axis xyz="1 0 0"/>
  </joint>
  <link name="servo_lower_knee_right">
    <collision>
      <origin rpy="0 0 0" xyz="-0.05694 4.06e-3 64.75e-3"/>
      <geometry>
        <mesh filename="package://raider_description/meshes/leg_right/servo_lower_knee_right.dae" scale="0.001 0.001 0.001"/>
      </geometry>
    </collision>
    <visual>
      <origin rpy="0 0 0" xyz="-0.05694 4.06e-3 64.75e-3"/>
      <geometry>
        <mesh filename="package://raider_description/meshes/leg_right/servo_lower_knee_right.dae" scale="0.001 0.001 0.001"/>
      </geometry>
    </visual>
    <inertial>
      <origin rpy="0 0 0" xyz="0.033059711 -16.859426e-3 -97.997299e-3"/>
      <mass value="0.055"/>
      <inertia ixx="13.3648128854" ixy="-0.11423240803" ixz="-0.00257091338332" iyy="8.72746489408" iyz="0.0011773616887" izz="15.8322542094"/>
    </inertial>
  </link>
  <joint name="joint_servolowerknee_kneedamper1_right" type="fixed">
    <origin xyz="0 0 0"/>
    <parent link="knee_damper_1_right"/>
    <child link="servo_lower_knee_right"/>
  </joint>
  <link name="knee_damper_1_right">
    <collision>
      <origin rpy="0 0 0" xyz="-0.05694 4.06e-3 64.75e-3"/>
      <geometry>
        <mesh filename="package://raider_description/meshes/leg_right/knee_damperright_1.dae" scale="0.001 0.001 0.001"/>
      </geometry>
    </collision>
    <visual>
      <origin rpy="0 0 0" xyz="-0.05694 4.06e-3 64.75e-3"/>
      <geometry>
        <mesh filename="package://raider_description/meshes/leg_right/knee_damperright_1.dae" scale="0.001 0.001 0.001"/>
      </geometry>
    </visual>
    <inertial>
      <origin rpy="0 0 0" xyz="0.049524082 -31.720390e-3 -78.538048e-3"/>
      <mass value="2e-3"/>
      <inertia ixx="0.423026673" ixy="0.007535722" ixz="-0.00201741" iyy="0.136987356" iyz="0.067385341" izz="0.290494473"/>
    </inertial>
  </link>
  <link name="knee_damper_2_right">
    <collision>
      <origin rpy="0 0 0" xyz="-0.05694 4.06e-3 64.75e-3"/>
      <geometry>
        <mesh filename="package://raider_description/meshes/leg_right/knee_damperright_2.dae" scale="0.001 0.001 0.001"/>
      </geometry>
    </collision>
    <visual>
      <origin rpy="0 0 0" xyz="-0.05694 4.06e-3 64.75e-3"/>
      <geometry>
        <mesh filename="package://raider_description/meshes/leg_right/knee_damperright_2.dae" scale="0.001 0.001 0.001"/>
      </geometry>
    </visual>
    <inertial>
      <origin rpy="0 0 0" xyz="0.014675918 -31.720392e-3 -78.538040e-3"/>
      <mass value="2e-3"/>
      <inertia ixx="0.423026894489" ixy="-0.00753540714801" ixz="0.00201733869804" iyy="0.13698782028" iyz="0.0673854098023" izz="0.290494829316"/>
    </inertial>
  </link>
  <joint name="joint_damper2leg_servoupperknee_right" type="fixed">
    <origin xyz="0 0 0"/>
    <parent link="servo_upper_knee_right"/>
    <child link="knee_damper_2_right"/>
  </joint>
  <joint name="joint_damper1leg_servoupperknee_right" type="fixed">
    <origin xyz="0 0 0"/>
    <parent link="servo_upper_knee_right"/>
    <child link="knee_damper_1_right"/>
  </joint>
  <link name="servo_upper_knee_right">
    <collision>
      <origin rpy="0 0 0" xyz="-0.05694 4.06e-3 64.75e-3"/>
      <geometry>
        <mesh filename="package://raider_description/meshes/leg_right/servo_upperright_knee.dae" scale="0.001 0.001 0.001"/>
      </geometry>
    </collision>
    <visual>
      <origin rpy="0 0 0" xyz="-0.05694 4.06e-3 64.75e-3"/>
      <geometry>
        <mesh filename="package://raider_description/meshes/leg_right/servo_upperright_knee.dae" scale="0.001 0.001 0.001"/>
      </geometry>
    </visual>
    <inertial>
      <origin rpy="0 0 0" xyz="0.033059711 -16.859426e-3 -65.997299e-3"/>
      <mass value="0.055"/>
      <inertia ixx="13.3726780935" ixy="-0.117182581594" ixz="-0.00257237409081" iyy="8.73145293176" iyz="0.00118132163081" izz="15.8415064767"/>
    </inertial>
  </link>
  <joint name="upper_knee_right" type="revolute">
    <dynamics damping="0.0" friction="0.0"/>
    <origin rpy="0 0 0" xyz="0 0 -73.75e-3"/>
    <limit effort="100" lower="-1.57079632679" upper="1.57079632679" velocity="3"/>
    <parent link="upper_leg_right"/>
    <child link="servo_upper_knee_right"/>
  </joint>
  <link name="upper_leg_right">
    <collision>
      <origin rpy="0 0 0" xyz="-0.05694 4.06e-3 -9e-3"/>
      <geometry>
        <mesh filename="package://raider_description/meshes/leg_right/upper_leg_right.dae" scale="0.001 0.001 0.001"/>
      </geometry>
    </collision>
    <visual>
      <origin rpy="0 0 0" xyz="-0.05694 4.06e-3 -9e-3"/>
      <geometry>
        <mesh filename="package://raider_description/meshes/leg_right/upper_leg_right.dae" scale="0.001 0.001 0.001"/>
      </geometry>
    </visual>
    <inertial>
      <origin rpy="0 0 0" xyz="0.033380638 -0.118964e-3 -33.265591e-3"/>
      <mass value="23e-3"/>
      <inertia ixx="16.287494127" ixy="0.039940722" ixz="-0.048285696" iyy="24.786351073" iyz="1.256185001" izz="12.170186251"/>
    </inertial>
  </link>
  <joint name="hip_right_swing" type="revolute">
    <dynamics damping="0.0" friction="0.0"/>
    <limit effort="100" lower="-1.57079632679" upper="1.57079632679" velocity="3"/>
    <origin rpy="0 0 0" xyz="0.02494 56.94e-3 0"/>
    <parent link="servo_upper_front_right"/>
    <child link="upper_leg_right"/>
  </joint>
  <link name="servo_upper_front_right">
    <collision>
      <origin rpy="0 0 0" xyz="-0.032 61e-3 -9e-3"/>
      <geometry>
        <mesh filename="package://raider_description/meshes/leg_right/servo_upperright_front.dae" scale="0.001 0.001 0.001"/>
      </geometry>
    </collision>
    <visual>
      <origin rpy="0 0 0" xyz="-0.032 61e-3 -9e-3"/>
      <geometry>
        <mesh filename="package://raider_description/meshes/leg_right/servo_upperright_front.dae" scale="0.001 0.001 0.001"/>
      </geometry>
    </visual>
    <inertial>
      <origin rpy="0 0 0" xyz="0.033259712 -4.062710e-3 -3.799430e-3"/>
      <mass value="0.055"/>
      <inertia ixx="13.3648128854" ixy="0.000243300048112" ixz="-0.114233548786" iyy="15.832252894" iyz="-0.00117736473926" izz="8.72746489408"/>
    </inertial>
  </link>
  <joint name="joint_servoupperfront_tobright" type="fixed">
    <origin xyz="0 0 0"/>
    <parent link="servo_upper_front_right"/>
    <child link="tob_right"/>
  </joint>
  <link name="tob_right">
    <collision>
      <origin rpy="0 0 0" xyz="-0.032 61e-3 -9e-3"/>
      <geometry>
        <mesh filename="package://raider_description/meshes/leg_right/tob_right.dae" scale="0.001 0.001 0.001"/>
      </geometry>
    </collision>
    <visual>
      <origin rpy="0 0 0" xyz="-0.032 61e-3 -9e-3"/>
      <geometry>
        <mesh filename="package://raider_description/meshes/leg_right/tob_right.dae" scale="0.001 0.001 0.001"/>
      </geometry>
    </visual>
    <inertial>
      <origin rpy="0 0 0" xyz="0.031999987 12.549569e-3 -5.968293e-3"/>
      <mass value="7e-3"/>
      <inertia ixx="0.998184661" ixy="-1.004e-06" ixz="1.021e-06" iyy="1.627441646" iyz="-0.005152814" izz="0.669885346"/>
    </inertial>
  </link>
  <joint name="jointright_servoupperfront_groin2" type="fixed">
    <origin xyz="0 0 0"/>
    <parent link="groin2_right"/>
    <child link="servo_upper_front_right"/>
  </joint>
  <link name="groin2_right">
    <collision>
      <origin rpy="0 0 0" xyz="-0.032 61e-3 -9e-3"/>
      <geometry>
        <mesh filename="package://raider_description/meshes/leg_right/groin2_right.dae" scale="0.001 0.001 0.001"/>
      </geometry>
    </collision>
    <visual>
      <origin rpy="0 0 0" xyz="-0.032 61e-3 -9e-3"/>
      <geometry>
        <mesh filename="package://raider_description/meshes/leg_right/groin2_right.dae" scale="0.001 0.001 0.001"/>
      </geometry>
    </visual>
    <inertial>
      <origin rpy="0 0 0" xyz="0.016159353 -35.801258e-3 -7.292182e-3"/>
      <mass value="5e-3"/>
      <inertia ixx="0.964450567" ixy="-0.032521998" ixz="0.003002097" iyy="0.377541101" iyz="0.088795829" izz="0.612968817"/>
    </inertial>
  </link>
  <joint name="jointright_servoupperback_groin1" type="fixed">
    <origin rpy="0 0 -3.14159265359" xyz="0 0.04378 0"/>
    <parent link="servo_upper_back_right"/>
    <child link="groin2_right"/>
  </joint>
  <link name="groin1_right">
    <collision>
      <origin rpy="0 0 0" xyz="-0.032 61e-3 -9e-3"/>
      <geometry>
        <mesh filename="package://raider_description/meshes/leg_right/groin1_right.dae" scale="0.001 0.001 0.001"/>
      </geometry>
    </collision>
    <visual>
      <origin rpy="0 0 0" xyz="-0.032 61e-3 -9e-3"/>
      <geometry>
        <mesh filename="package://raider_description/meshes/leg_right/groin1_right.dae" scale="0.001 0.001 0.001"/>
      </geometry>
    </visual>
    <inertial>
      <origin rpy="0 0 0" xyz="0.047840645 -35.801262e-3 -7.292187e-3"/>
      <mass value="5e-3"/>
      <inertia ixx="0.964451283" ixy="0.032521697" ixz="-0.003002165" iyy="0.377541141" iyz="0.08879578" izz="0.612969334"/>
    </inertial>
  </link>
  <joint name="joint_servoupperback_groin1_right" type="fixed">
    <origin rpy="0 0 -3.14159265359" xyz="0 0.04378 0"/>
    <parent link="servo_upper_back_right"/>
    <child link="groin1_right"/>
  </joint>
  <link name="servo_upper_back_right">
    <collision>
      <origin rpy="0 0 0" xyz="-0.032 61e-3 -9e-3"/>
      <geometry>
        <mesh filename="package://raider_description/meshes/leg_right/servo_upperright_back.dae" scale="0.001 0.001 0.001"/>
      </geometry>
    </collision>
    <visual>
      <origin rpy="0 0 0" xyz="-0.032 61e-3 -9e-3"/>
      <geometry>
        <mesh filename="package://raider_description/meshes/leg_right/servo_upperright_back.dae" scale="0.001 0.001 0.001"/>
      </geometry>
    </visual>
    <inertial>
      <origin rpy="0 0 0" xyz="0.031997288 -37.115585e-3 -3.810416e-3"/>
      <mass value="0.055"/>
      <inertia ixx="15.832250263" ixy="-0.000243300047342" ixz="-0.00117736064422" iyy="13.3648128854" iyz="0.114233158256" izz="8.72746818275"/>
    </inertial>
  </link>
  <joint name="groin_right" type="revolute">
    <limit effort="100" lower="-1.57079632679" upper="1.57079632679" velocity="3"/>
    <origin rpy="0 0.0 3.14159265359" xyz="0 0.00378 -0.022"/>
    <parent link="leg_bracket_right"/>
    <child link="servo_upper_back_right"/>
    <axis xyz="0 1 0"/>
  </joint>
  <link name="leg_bracket_right">
    <collision>
      <origin rpy="0 0 0" xyz="-0.032 21e-3 -31e-3"/>
      <geometry>
        <mesh filename="package://raider_description/meshes/leg_right/leg_bracket_right.dae" scale="0.001 0.001 0.001"/>
      </geometry>
    </collision>
    <visual>
      <origin rpy="0 0 0" xyz="-0.032 21e-3 -31e-3"/>
      <geometry>
        <mesh filename="package://raider_description/meshes/leg_right/leg_bracket_right.dae" scale="0.001 0.001 0.001"/>
      </geometry>
    </visual>
    <inertial>
      <origin rpy="0 0 0" xyz="0.031468872 -22.709967e-3 27.662817e-3"/>
      <mass value="17e-3"/>
      <inertia ixx="14.953408409" ixy="0.236958746" ixz="0.081847589" iyy="0.281864658" iyz="-0.318501245" izz="14.972208875"/>
    </inertial>
  </link>
  <link name="chest_chassis">
    <collision>
      <origin rpy="0 0 0" xyz="31.26e-3 0 -76.94e-3"/>
      <geometry>
        <mesh filename="package://raider_description/meshes/chest/chest.dae" scale="0.001 0.001 0.001"/>
      </geometry>
    </collision>
    <visual>
      <origin rpy="0 0 0" xyz="31.26e-3 0 -76.94e-3"/>
      <geometry>
        <mesh filename="package://raider_description/meshes/chest/chest.dae" scale="0.001 0.001 0.001"/>
      </geometry>
    </visual>
    <inertial>
      <origin rpy="0 0 0" xyz="-30.867216e-3 -3.980905e-3 103.660454e-3"/>
      <mass value="69e-3"/>
      <inertia ixx="68.633104082" ixy="-0.247155947" ixz="-1.001142952" iyy="111.479482676" iyz="-2.775691149" izz="106.026365641"/>
    </inertial>
  </link>
  <joint name="battery_servohip_middle" type="fixed">
    <dynamics damping="0.0" friction="10.0"/>
    <parent link="servo_hip_middle"/>
    <child link="battery_support"/>
    <origin xyz="0 0 0"/>
  </joint>
  <link name="battery_support">
    <collision>
      <origin rpy="0 0 0" xyz="0 0 0"/>
      <geometry>
        <mesh filename="package://raider_description/meshes/chest/battery_support.dae" scale="0.001 0.001 0.001"/>
      </geometry>
    </collision>
    <visual>
      <origin rpy="0 0 0" xyz="0 0 0"/>
      <geometry>
        <mesh filename="package://raider_description/meshes/chest/battery_support.dae" scale="0.001 0.001 0.001"/>
      </geometry>
    </visual>
    <inertial>
      <origin rpy="0 0 0" xyz="0 -51.127079e-3 258.000061e-3"/>
      <mass value="10e-3"/>
      <inertia ixx="3.170596051" ixy="-0.000000784" ixz="-0000001" iyy="5.376089166" iyz="0.000012792" izz="3.687439427"/>
    </inertial>
  </link>
  <joint name="joint_battery_support" type="fixed">
    <dynamics damping="0.0" friction="10.0"/>
    <parent link="battery_support"/>
    <child link="battery"/>
    <origin xyz="0 0 0"/>
  </joint>
  <link name="battery">
    <collision>
      <origin rpy="0 0 0" xyz="0 0 0"/>
      <geometry>
        <mesh filename="package://raider_description/meshes/chest/battery.dae" scale="0.001 0.001 0.001"/>
      </geometry>
    </collision>
    <visual>
      <origin rpy="0 0 0" xyz="0 0 0"/>
      <geometry>
        <mesh filename="package://raider_description/meshes/chest/battery.dae" scale="0.001 0.001 0.001"/>
      </geometry>
    </visual>
    <inertial>
      <origin rpy="0 0 0" xyz="-30.197001e-3 -44.700001e-3 91.440002e-3"/>
      <mass value="158e-3"/>
      <inertia ixx="22109.350504618" ixy="-0.001350018" ixz="0.003879992" iyy="128618.785627577" iyz="0.037398901" izz="122602.078416133"/>
    </inertial>
  </link>
  <joint name="joint_accelerometer_chest" type="fixed">
    <dynamics damping="0.0" friction="10.0"/>
    <parent link="chest_chassis"/>
    <child link="accelerometer"/>
    <origin xyz="30.67e-3 -25.94e-3 -4e-3"/>
  </joint>
  <!--joint name="joint_accelerometer_chest" type="revolute">
      <dynamics damping="0.0" friction="0.0"/>
      <limit upper="0" lower="0" velocity="0" effort="100"/>
      <parent link="chest_chassis"/>
      <child link="accelerometer"/>
      <origin xyz="30.67e-3 -25.94e-3 -4e-3"/>
      <axis xyz="0 1 0"/>
    </joint-->
  <link name="accelerometer">
    <collision>
      <origin rpy="0 0 0" xyz="0.67e-3 25.94e-3 -149.88e-3"/>
      <geometry>
        <mesh filename="package://raider_description/meshes/chest/accelerometer.dae" scale="0.001 0.001 0.001"/>
      </geometry>
    </collision>
    <visual>
      <origin rpy="0 0 0" xyz="0.67e-3 25.94e-3 -149.88e-3"/>
      <geometry>
        <mesh filename="package://raider_description/meshes/chest/accelerometer.dae" scale="0.001 0.001 0.001"/>
      </geometry>
    </visual>
    <inertial>
      <origin rpy="0 0 0" xyz="-1.480880e-3 -27.624779e-3 81.529266e-3"/>
      <mass value="1e-3"/>
      <inertia ixx="0.021407978" ixy="-0.000455369" ixz="0.000088787" iyy="0.050323934" iyz="0.000335926" izz="0.07141742"/>
    </inertial>
  </link>
  <joint name="servoshoulderleft_chest" type="fixed">
    <dynamics damping="0.0" friction="10.0"/>
    <parent link="chest_chassis"/>
    <child link="servo_shoulder_left"/>
    <origin xyz="31.26e-3 0 -76.94e-3"/>
  </joint>
  <link name="servo_shoulder_left">
    <collision>
      <origin rpy="0 0 0" xyz="0 0 0"/>
      <geometry>
        <mesh filename="package://raider_description/meshes/chest/servo_shoulder_left.dae" scale="0.001 0.001 0.001"/>
      </geometry>
    </collision>
    <visual>
      <origin rpy="0 0 0" xyz="0 0 0"/>
      <geometry>
        <mesh filename="package://raider_description/meshes/chest/servo_shoulder_left.dae" scale="0.001 0.001 0.001"/>
      </geometry>
    </visual>
    <inertial>
      <origin rpy="0 0 0" xyz="-63.315582e-3 3.302713e-3 107.129585e-3"/>
      <mass value="0.055"/>
      <inertia ixx="13.3648339995" ixy="0.0025720102203" ixz="0.114243959064" iyy="15.8322777238" iyz="0.00117643238643" izz="8.72745750121"/>
    </inertial>
  </link>
  <joint name="servoshoulderright_chest" type="fixed">
    <dynamics damping="0.0" friction="10.0"/>
    <parent link="chest_chassis"/>
    <child link="servo_shoulder_right"/>
    <origin xyz="31.26e-3 0 -76.94e-3"/>
  </joint>
  <link name="servo_shoulder_right">
    <collision>
      <origin rpy="0 0 0" xyz="0 0 0"/>
      <geometry>
        <mesh filename="package://raider_description/meshes/chest/servo_shoulder_right.dae" scale="0.001 0.001 0.001"/>
      </geometry>
    </collision>
    <visual>
      <origin rpy="0 0 0" xyz="0 0 0"/>
      <geometry>
        <mesh filename="package://raider_description/meshes/chest/servo_shoulder_right.dae" scale="0.001 0.001 0.001"/>
      </geometry>
    </visual>
    <inertial>
      <origin rpy="0 0 0" xyz="0.799711e-3 3.297292e-3 107.140572e-3"/>
      <mass value="0.055"/>
      <inertia ixx="13.3804617302" ixy="0.00257396479163" ixz="-0.117251637441" iyy="15.8507679076" iyz="-0.00118145667161" izz="8.7365644692"/>
    </inertial>
  </link>
  <!--joint name="ultrasonic_chest" type="fixed">
      <dynamics damping="0.0" friction="10.0"/>
      <parent link="chest_chassis"/>
      <child link="ultrasonic_sensor"/>
      <origin xyz="2.26e-3 27.4e-3 30e-3"/>
    </joint-->
  <joint name="ultrasonic_chest" type="fixed">
    <parent link="chest_chassis"/>
    <child link="ultrasonic_sensor"/>
    <origin rpy="0 0 1.57079632679" xyz="2.26e-3 27.4e-3 30e-3"/>
    <axis xyz="0 1 0"/>
  </joint>
  <link name="ultrasonic_sensor">
    <collision>
      <origin rpy="0 0 -1.57079632679" xyz="-27.5e-3 -27.4e-3 -106e-3"/>
      <geometry>
        <mesh filename="package://raider_description/meshes/chest/ultrasonic.dae" scale="0.001 0.001 0.001"/>
      </geometry>
    </collision>
    <visual>
      <origin rpy="0 0 -1.57079632679" xyz="-27.5e-3 -27.4e-3 -106e-3"/>
      <geometry>
        <mesh filename="package://raider_description/meshes/chest/ultrasonic.dae" scale="0.001 0.001 0.001"/>
      </geometry>
    </visual>
    <inertial>
      <origin rpy="0 0 0" xyz="-28.759998e-3 27.106962e-3 106.563263e-3"/>
      <mass value="10e-3"/>
      <inertia ixx="0.466992314" ixy="0.000000648" ixz="-0.000002151" iyy="2.144495716" iyz="0.006837363" izz="0.000208781"/>
    </inertial>
  </link>
  <joint name="compass_chest" type="fixed">
    <dynamics damping="0.0" friction="10.0"/>
    <parent link="chest_chassis"/>
    <child link="compass"/>
    <origin xyz="-42.52e-3 0 58.46e-3"/>
  </joint>
  <!--joint name="compass_chest" type="revolute">
      <dynamics damping="0.0" friction="0.0"/>
      <limit upper="0" lower="0" velocity="0" effort="100"/>
      <parent link="chest_chassis"/>
      <child link="compass"/>
      <origin xyz="-42.52e-3 0 58.46e-3"/>
      <axis xyz="0 1 0"/>
    </joint-->
  <link name="compass">
    <collision>
      <origin rpy="0 0 0" xyz="73.78e-3 0 -135.4e-3"/>
      <geometry>
        <mesh filename="package://raider_description/meshes/chest/compass.dae" scale="0.001 0.001 0.001"/>
      </geometry>
    </collision>
    <visual>
      <origin rpy="0 0 0" xyz="73.78e-3 0 -135.4e-3"/>
      <geometry>
        <mesh filename="package://raider_description/meshes/chest/compass.dae" scale="0.001 0.001 0.001"/>
      </geometry>
    </visual>
    <inertial>
      <origin rpy="0 0 0" xyz="-68.874374e-3 6.414726e-3 134.550735e-3"/>
      <mass value="200e-3"/>
      <inertia ixx="15.998622965" ixy="0.228234406" ixz="0.019697434" iyy="9.471288583" iyz="-0.020465348" izz="25.385537633"/>
    </inertial>
  </link>
  <joint name="expansion_chest" type="fixed">
    <dynamics damping="0.0" friction="10.0"/>
    <parent link="chest_chassis"/>
    <child link="expansion_board"/>
    <origin xyz="31.26e-3 0 -76.94e-3"/>
  </joint>
  <link name="expansion_board">
    <collision>
      <origin rpy="0 0 0" xyz="0 0 0"/>
      <geometry>
        <mesh filename="package://raider_description/meshes/chest/expansion_board.dae" scale="0.001 0.001 0.001"/>
      </geometry>
    </collision>
    <visual>
      <origin rpy="0 0 0" xyz="0 0 0"/>
      <geometry>
        <mesh filename="package://raider_description/meshes/chest/expansion_board.dae" scale="0.001 0.001 0.001"/>
      </geometry>
    </visual>
    <inertial>
      <origin rpy="0 0 0" xyz="-30.476395e-3 -44.831921e-3 108.771057e-3"/>
      <mass value="35e-3"/>
      <inertia ixx="13.155683237" ixy="-0.019818245" ixz="-0.099426146" iyy="32.373101206" iyz="0.088507484" izz="19.455722737"/>
    </inertial>
  </link>
  <joint name="expansion_beaglebone" type="fixed">
    <parent link="expansion_board"/>
    <child link="beaglebone"/>
    <origin xyz="0 0 0"/>
  </joint>
  <link name="beaglebone">
    <collision>
      <origin rpy="0 0 0" xyz="0 0 0"/>
      <geometry>
        <mesh filename="package://raider_description/meshes/chest/beaglebone.dae" scale="0.001 0.001 0.001"/>
      </geometry>
    </collision>
    <visual>
      <origin rpy="0 0 0" xyz="0 0 0"/>
      <geometry>
        <mesh filename="package://raider_description/meshes/chest/beaglebone.dae" scale="0.001 0.001 0.001"/>
      </geometry>
    </visual>
    <inertial>
      <origin rpy="0 0 0" xyz="-34.425621e-3 -52.326832e-3 105.526978e-3"/>
      <mass value="40e-3"/>
      <inertia ixx="10.932820677" ixy="-1.111965118" ixz="0.114190384" iyy="36.394534502" iyz="-0.011368874" izz="26.531304424"/>
    </inertial>
  </link>
  <joint name="expansion_ubec" type="fixed">
    <parent link="expansion_board"/>
    <child link="ubec"/>
    <origin xyz="0 0 0"/>
  </joint>
  <link name="ubec">
    <collision>
      <origin rpy="0 0 0" xyz="0 0 0"/>
      <geometry>
        <mesh filename="package://raider_description/meshes/chest/ubec.dae" scale="0.001 0.001 0.001"/>
      </geometry>
    </collision>
    <visual>
      <origin rpy="0 0 0" xyz="0 0 0"/>
      <geometry>
        <mesh filename="package://raider_description/meshes/chest/ubec.dae" scale="0.001 0.001 0.001"/>
      </geometry>
    </visual>
    <inertial>
      <origin rpy="0 0 0" xyz="3.117789e-3 -38.962219e-3 305.25e-3"/>
      <mass value="7.5e-3"/>
      <inertia ixx="0.449869869" ixy="0.013904256" ixz="-0.000000129" iyy="2.367011516" iyz="-0.000000652" izz="2.033599244"/>
    </inertial>
  </link>
  <!-- Head -->
  <joint name="chest_microservo" type="fixed">
    <parent link="chest_chassis"/>
    <child link="microservo"/>
    <origin xyz="31.26e-3 0 -76.94e-3"/>
  </joint>
  <link name="microservo">
    <collision>
      <origin rpy="0 0 0" xyz="0 0 0"/>
      <geometry>
        <mesh filename="package://raider_description/meshes/head/microservo.dae" scale="0.001 0.001 0.001"/>
      </geometry>
    </collision>
    <visual>
      <origin rpy="0 0 0" xyz="0 0 0"/>
      <geometry>
        <mesh filename="package://raider_description/meshes/head/microservo.dae" scale="0.001 0.001 0.001"/>
      </geometry>
    </visual>
    <inertial>
      <origin rpy="0 0 0" xyz="-34.699566e-3 6.703261e-3 139.939987e-3"/>
      <mass value="13.4e-3"/>
      <inertia ixx="0.79631024" ixy="0.071080342" ixz="0.000010505" iyy="0.707342537" iyz="-0.000000896" izz="1.203373945"/>
    </inertial>
  </link>
  <joint name="neck" type="revolute">
    <dynamics damping="0.0" friction="0.0"/>
    <limit effort="100" lower="-1" upper="0" velocity="3"/>
    <parent link="chest_chassis"/>
    <child link="head"/>
    <origin xyz="31.26e-3 12.1e-3 63e-3"/>
    <axis xyz="1 0 0"/>
  </joint>
  <link name="head">
    <collision>
      <origin rpy="0 0 0" xyz="0 -12.1e-3 -139.94e-3"/>
      <geometry>
        <mesh filename="package://raider_description/meshes/head/head.dae" scale="0.001 0.001 0.001"/>
      </geometry>
    </collision>
    <visual>
      <origin rpy="0 0 0" xyz="0 -12.1e-3 -139.94e-3"/>
      <geometry>
        <mesh filename="package://raider_description/meshes/head/head.dae" scale="0.001 0.001 0.001"/>
      </geometry>
    </visual>
    <inertial>
      <origin rpy="0 0 0" xyz="-31.180738e-3 -2.366833e-3 164.260635e-3"/>
      <mass value="44e-3"/>
      <inertia ixx="23.419764683" ixy="-0.17967725" ixz="0.136503491" iyy="17.645258196" iyz="0.830629778" izz="26.684106335"/>
    </inertial>
  </link>
  <joint name="arm_microservo_joint" type="fixed">
    <dynamics damping="0.0" friction="10.0"/>
    <parent link="head"/>
    <child link="arm_microservo"/>
    <origin xyz="0 -12.1e-3 -139.94e-3"/>
  </joint>
  <link name="arm_microservo">
    <collision>
      <origin rpy="0 0 0" xyz="0 0 0"/>
      <geometry>
        <mesh filename="package://raider_description/meshes/head/arm_microservo.dae" scale="0.001 0.001 0.001"/>
      </geometry>
    </collision>
    <visual>
      <origin rpy="0 0 0" xyz="0 0 0"/>
      <geometry>
        <mesh filename="package://raider_description/meshes/head/arm_microservo.dae" scale="0.001 0.001 0.001"/>
      </geometry>
    </visual>
    <inertial>
      <origin rpy="0 0 0" xyz="-49.879631e-3 9.112244e-3 143.111343e-3"/>
      <mass value="1e-3"/>
      <inertia ixx="0.034414067" ixy="-0.002039668" ixz="0.001999204" iyy="0.017986123" iyz="0.014190635" izz="0.01857552"/>
    </inertial>
  </link>
  <joint name="head_chassis_lifecam" type="fixed">
    <dynamics damping="0.0" friction="10.0"/>
    <parent link="head"/>
    <child link="chassis_lifecam"/>
    <origin xyz="0 -12.1e-3 -139.94e-3"/>
  </joint>
  <link name="chassis_lifecam">
    <collision>
      <origin rpy="0 0 0" xyz="0 0 0"/>
      <geometry>
        <mesh filename="package://raider_description/meshes/head/chassis_lifecam.dae" scale="0.001 0.001 0.001"/>
      </geometry>
    </collision>
    <visual>
      <origin rpy="0 0 0" xyz="0 0 0"/>
      <geometry>
        <mesh filename="package://raider_description/meshes/head/chassis_lifecam.dae" scale="0.001 0.001 0.001"/>
      </geometry>
    </visual>
    <inertial>
      <origin rpy="0 0 0" xyz="-31.209848e-3 19.280575e-3 167.859589e-3"/>
      <mass value="3e-3"/>
      <inertia ixx="0.151655121" ixy="0.000177538" ixz="-0.001218298" iyy="0.384780168" iyz="-0.000285021" izz="0.278011012"/>
    </inertial>
  </link>
  <joint name="cover_head" type="fixed">
    <dynamics damping="0.0" friction="10.0"/>
    <parent link="head"/>
    <child link="cover_head"/>
    <origin xyz="0 -12.1e-3 -139.94e-3"/>
  </joint>
  <link name="cover_head">
    <collision>
      <origin rpy="0 0 0" xyz="0 0 0"/>
      <geometry>
        <mesh filename="package://raider_description/meshes/head/cover_head.dae" scale="0.001 0.001 0.001"/>
      </geometry>
    </collision>
    <visual>
      <origin rpy="0 0 0" xyz="0 0 0"/>
      <geometry>
        <mesh filename="package://raider_description/meshes/head/cover_head.dae" scale="0.001 0.001 0.001"/>
      </geometry>
    </visual>
    <inertial>
      <origin rpy="0 0 0" xyz="-24.260002e-3 -35.900002e-3 161.992737e-3"/>
      <mass value="3e-4"/>
      <inertia ixx="0.001401112" ixy="0.000000002" ixz="-0.00000033" iyy="0.011750281" iyz="0.000000934" izz="0.010548865"/>
    </inertial>
  </link>
  <joint name="lifecam_to_chassis" type="fixed">
    <dynamics damping="0.0" friction="10.0"/>
    <parent link="chassis_lifecam"/>
    <child link="lifecam"/>
    <origin rpy="0 0 1.57079632679" xyz="-31.5e-3 25e-3 167.9e-3"/>
  </joint>
  <link name="lifecam">
    <collision>
      <origin rpy="0 0 -1.57079632679" xyz="-25e-3 -31.5e-3 -167.9e-3"/>
      <geometry>
        <mesh filename="package://raider_description/meshes/head/lifecam.dae" scale="0.001 0.001 0.001"/>
      </geometry>
    </collision>
    <visual>
      <origin rpy="0 0 -1.57079632679" xyz="-25e-3 -31.5e-3 -167.9e-3"/>
      <geometry>
        <mesh filename="package://raider_description/meshes/head/lifecam.dae" scale="0.001 0.001 0.001"/>
      </geometry>
    </visual>
    <inertial>
      <origin rpy="0 0 0" xyz="-31.260019e-3 13.105232e-3 167.940002e-3"/>
      <mass value="95.3e-3"/>
      <inertia ixx="6.166010606" ixy="-0.000004779" ixz="0.000019444" iyy="3.256684062" iyz="0.000002913" izz="6.494934716"/>
    </inertial>
  </link>
  <!--Arm right -->
  <joint name="shoulder_right_swing" type="revolute">
    <dynamics damping="0.0" friction="0.0"/>
    <limit effort="100" lower="-3.14159265359" upper="3.14159265359" velocity="3"/>
    <parent link="servo_shoulder_right"/>
    <child link="shoulder_right"/>
    <origin xyz="19.74e-3 3.3e-3 119.94e-3"/>
    <axis xyz="1 0 0"/>
  </joint>
  <link name="shoulder_right">
    <collision>
      <origin rpy="0 0 0" xyz="-0.01974 -3.3e-3 -119.94e-3"/>
      <geometry>
        <mesh filename="package://raider_description/meshes/arm_right/shoulder_right.dae" scale="0.001 0.001 0.001"/>
      </geometry>
    </collision>
    <visual>
      <origin rpy="0 0 0" xyz="-0.01974 -3.3e-3 -119.94e-3"/>
      <geometry>
        <mesh filename="package://raider_description/meshes/arm_right/shoulder_right.dae" scale="0.001 0.001 0.001"/>
      </geometry>
    </visual>
    <inertial>
      <origin rpy="0 0 0" xyz="0.041306133 3.409524e-3 129.948502e-3"/>
      <mass value="26e-3"/>
      <inertia ixx="11.710303909" ixy="0.000355401" ixz="1.402315479" iyy="9.349656034" iyz="0.000185333" izz="14.505300259"/>
    </inertial>
  </link>
  <joint name="shoulder_right_lateral" type="revolute">
    <dynamics damping="0.0" friction="0.0"/>
    <limit effort="100" lower="-1.5" upper="1.5" velocity="3"/>
    <parent link="shoulder_right"/>
    <child link="servo_upper_arm_right"/>
    <origin rpy="0 -0.0910695 0.0" xyz="0.024 0 -1e-3"/>
    <axis xyz="0 1 0"/>
  </joint>
  <link name="servo_upper_arm_right">
    <collision>
      <origin rpy="0 0 0" xyz="-0.04374 -4e-3 -118.94e-3"/>
      <geometry>
        <mesh filename="package://raider_description/meshes/arm_right/servo_upper_arm_right.dae" scale="0.001 0.001 0.001"/>
      </geometry>
    </collision>
    <visual>
      <origin rpy="0 0 0" xyz="-0.04374  -4e-3 -118.94e-3"/>
      <geometry>
        <mesh filename="package://raider_description/meshes/arm_right/servo_upper_arm_right.dae" scale="0.001 0.001 0.001"/>
      </geometry>
    </visual>
    <inertial>
      <origin rpy="0 0 0" xyz="0.076059296 3.228505e-3 308.337189e-3"/>
      <mass value="0.055"/>
      <inertia ixx="15.7877487408" ixy="0.00765350004071" ixz="0.618535858694" iyy="13.3731973321" iyz="-0.116966859215" izz="8.7856698187"/>
    </inertial>
  </link>
  <joint name="joint_servo_upperarm_union1_right" type="fixed">
    <dynamics damping="0.0" friction="10.0"/>
    <parent link="servo_upper_arm_right"/>
    <child link="union1_servo_right"/>
    <origin rpy="0 0 0.0" xyz="0 0 0"/>
  </joint>
  <link name="union1_servo_right">
    <collision>
      <origin xyz="-0.04374 -4e-3 -118.94e-3"/>
      <geometry>
        <mesh filename="package://raider_description/meshes/arm_right/union1_servo_right.dae" scale="0.001 0.001 0.001"/>
      </geometry>
    </collision>
    <visual>
      <origin xyz="-0.04374 -4e-3 -118.94e-3"/>
      <geometry>
        <mesh filename="package://raider_description/meshes/arm_right/union1_servo_right.dae" scale="0.001 0.001 0.001"/>
      </geometry>
    </visual>
    <inertial>
      <origin rpy="0 0 0" xyz="0.045191589 3.468790e-3 80.072578e-3"/>
      <mass value="4e-3"/>
      <inertia ixx="0.590627758" ixy="-1.5e-07" ixz="-0.019347738" iyy="0.251187499" iyz="0.00000012" izz="0.811914984"/>
    </inertial>
  </link>
  <joint name="joint_servo_upperarm_union2_right" type="fixed">
    <dynamics damping="0.0" friction="10.0"/>
    <parent link="servo_upper_arm_right"/>
    <child link="union2_servo_right"/>
    <origin rpy="0 0 0.0" xyz="0 0 0"/>
  </joint>
  <link name="union2_servo_right">
    <collision>
      <origin xyz="-0.04374 -4e-3 -118.94e-3"/>
      <geometry>
        <mesh filename="package://raider_description/meshes/arm_right/union2_servo_right.dae" scale="0.001 0.001 0.001"/>
      </geometry>
    </collision>
    <visual>
      <origin xyz="-0.04374 -4e-3 -118.94e-3"/>
      <geometry>
        <mesh filename="package://raider_description/meshes/arm_right/union2_servo_right.dae" scale="0.001 0.001 0.001"/>
      </geometry>
    </visual>
    <inertial>
      <origin rpy="0 0 0" xyz="0.045626991 3.451273e-3 75.296814e-3"/>
      <mass value="4e-3"/>
      <inertia ixx="0.255461633" ixy="1.4093e-05" ixz="-0.048831278" iyy="0.588954525" iyz="-0.000159133" izz="0.809321022"/>
    </inertial>
  </link>
  <joint name="joint_servo_elbowunion_right" type="fixed">
    <dynamics damping="0.0" friction="10.0"/>
    <parent link="union2_servo_right"/>
    <child link="servo_elbow_right"/>
    <origin xyz="0 0 0"/>
  </joint>
  <link name="servo_elbow_right">
    <collision>
      <origin xyz="-0.04374 -4e-3 -118.94e-3"/>
      <geometry>
        <mesh filename="package://raider_description/meshes/arm_right/servo_elbow_right.dae" scale="0.001 0.001 0.001"/>
      </geometry>
    </collision>
    <visual>
      <origin xyz="-0.04374 -4e-3 -118.94e-3"/>
      <geometry>
        <mesh filename="package://raider_description/meshes/arm_right/servo_elbow_right.dae" scale="0.001 0.001 0.001"/>
      </geometry>
    </visual>
    <inertial>
      <origin rpy="0 0 0" xyz="0.048971466 3.471508e-3 49.196182e-3"/>
      <mass value="0.055"/>
      <inertia ixx="13.3028676946" ixy="-0.00245297567846" ixz="0.515734556249" iyy="15.8250571706" iyz="-0.0013934917261" izz="8.77893463349"/>
    </inertial>
  </link>
  <joint name="elbow_right" type="revolute">
    <dynamics damping="0.0" friction="0.0"/>
    <limit effort="100" lower="-2.09439510239" upper="2.09439510239" velocity="3"/>
    <parent link="servo_elbow_right"/>
    <child link="elbow_right"/>
    <origin rpy="0 0 0" xyz="0 -0.5e-3 -82.65e-3"/>
    <axis xyz="1 0 0"/>
  </joint>
  <link name="elbow_right">
    <collision>
      <origin xyz="-0.04374 -3.5e-3 -36.29e-3"/>
      <geometry>
        <mesh filename="package://raider_description/meshes/arm_right/elbow_right.dae" scale="0.001 0.001 0.001"/>
      </geometry>
    </collision>
    <visual>
      <origin xyz="-0.04374 -3.5e-3 -36.29e-3"/>
      <geometry>
        <mesh filename="package://raider_description/meshes/arm_right/elbow_right.dae" scale="0.001 0.001 0.001"/>
      </geometry>
    </visual>
    <inertial>
      <origin rpy="0 0 0" xyz="0.0525494 7.686087e-3 26.149841e-3"/>
      <mass value="15e-3"/>
      <inertia ixx="4.397140534" ixy="-0.245999243" ixz="-0.927496479" iyy="8.263120442" iyz="-0.566498905" izz="6.876263573"/>
    </inertial>
  </link>
  <joint name="joint_elbow_forearm_right" type="fixed">
    <dynamics damping="0.0" friction="10.0"/>
    <parent link="elbow_right"/>
    <child link="forearm_right"/>
    <origin rpy="0 0 0" xyz="0 0 0"/>
  </joint>
  <link name="forearm_right">
    <collision>
      <origin xyz="-0.04374 -3.5e-3 -36.29e-3"/>
      <geometry>
        <mesh filename="package://raider_description/meshes/arm_right/forearm_right.dae" scale="0.001 0.001 0.001"/>
      </geometry>
    </collision>
    <visual>
      <origin xyz="-0.04374 -3.5e-3 -36.29e-3"/>
      <geometry>
        <mesh filename="package://raider_description/meshes/arm_right/forearm_right.dae" scale="0.001 0.001 0.001"/>
      </geometry>
    </visual>
    <inertial>
      <origin rpy="0 0 0" xyz="0.053241585 6.205578e-3 -1.415684e-3"/>
      <mass value="14e-3"/>
      <inertia ixx="3.440210914" ixy="-0.018232757" ixz="-0.095159818" iyy="4.001844032" iyz="0.207159085" izz="4.51976604"/>
    </inertial>
  </link>
  <joint name="joint_sharp_forearm_right" type="fixed">
    <dynamics damping="0.0" friction="10.0"/>
    <parent link="forearm_right"/>
    <child link="sharp_right"/>
    <origin rpy="0 0 -1.57079632679" xyz="-0.00403 -11.08e-3 -46.51e-3"/>
  </joint>
  <link name="sharp_right">
    <collision>
      <origin rpy="0 0 1.57079632679" xyz="-11.08e-3 -0.04097 10.22e-3"/>
      <geometry>
        <mesh filename="package://raider_description/meshes/arm_right/sharp_right.dae" scale="0.001 0.001 0.001"/>
      </geometry>
    </collision>
    <visual>
      <origin rpy="0 0 1.57079632679" xyz="-11.08e-3 -0.04097 10.22e-3"/>
      <geometry>
        <mesh filename="package://raider_description/meshes/arm_right/sharp_right.dae" scale="0.001 0.001 0.001"/>
      </geometry>
    </visual>
    <inertial>
      <origin rpy="0 0 0" xyz="0.055055099 -1.675636e-3 -6.841179e-3"/>
      <mass value="3.5e-3"/>
      <inertia ixx="0.084903021" ixy="-0.00951706" ixz="-0.023015952" iyy="0.338559496" iyz="0.006557898" izz="0.325236131"/>
    </inertial>
  </link>
  <joint name="joint_forearm_hand_right" type="fixed">
    <parent link="forearm_right"/>
    <child link="hand_right"/>
    <origin rpy="0 0 0" xyz="0 0 0"/>
  </joint>
  <link name="hand_right">
    <collision>
      <origin xyz="-0.04374 -3.5e-3 -36.29e-3"/>
      <geometry>
        <mesh filename="package://raider_description/meshes/arm_right/hand_right.dae" scale="0.001 0.001 0.001"/>
      </geometry>
    </collision>
    <visual>
      <origin xyz="-0.04374 -3.5e-3 -36.29e-3"/>
      <geometry>
        <mesh filename="package://raider_description/meshes/arm_right/hand_right.dae" scale="0.001 0.001 0.001"/>
      </geometry>
    </visual>
    <inertial>
      <origin rpy="0 0 0" xyz="0.057381317 7.527186e-3 -48.516449e-3"/>
      <mass value="34e-3"/>
      <inertia ixx="13.839519597" ixy="0.01601312" ixz="0.690764395" iyy="13.107441542" iyz="-0.183076833" izz="6.004466355"/>
    </inertial>
  </link>
  <!--Arm right -->
  <joint name="shoulder_left_swing" type="revolute">
    <dynamics damping="0.0" friction="0.0"/>
    <limit effort="100" lower="-3.14159265359" upper="3.14159265359" velocity="3"/>
    <parent link="servo_shoulder_left"/>
    <child link="shoulder_left"/>
    <origin xyz="-84.14e-3 3.3e-3 119.94e-3"/>
    <axis xyz="1 0 0"/>
  </joint>
  <link name="shoulder_left">
    <collision>
      <origin rpy="0 0 0" xyz="0.01974 -3.3e-3 -119.94e-3"/>
      <geometry>
        <mesh filename="package://raider_description/meshes/arm_left/shoulder_left.dae" scale="0.001 0.001 0.001"/>
      </geometry>
    </collision>
    <visual>
      <origin rpy="0 0 0" xyz="0.01974 -3.3e-3 -119.94e-3"/>
      <geometry>
        <mesh filename="package://raider_description/meshes/arm_left/shoulder_left.dae" scale="0.001 0.001 0.001"/>
      </geometry>
    </visual>
    <inertial>
      <origin rpy="0 0 0" xyz="-0.041306133 3.409524e-3 129.948502e-3"/>
      <mass value="26e-3"/>
      <inertia ixx="11.710303909" ixy="-0.000355401" ixz="-1.402315479" iyy="9.349656034" iyz="0.000185333" izz="14.505300259"/>
    </inertial>
  </link>
  <joint name="shoulder_left_lateral" type="revolute">
    <dynamics damping="0.0" friction="0.0"/>
    <limit effort="100" lower="-1.5" upper="1.5" velocity="3"/>
    <parent link="shoulder_left"/>
    <child link="servo_upper_arm_left"/>
    <origin rpy="0 -0.0910695 3.14159265359" xyz="-0.024 0 -1e-3"/>
    <axis xyz="0 1 0"/>
  </joint>
  <link name="servo_upper_arm_left">
    <collision>
      <origin rpy="0 0 0" xyz="0.04374 -4e-3 -118.94e-3"/>
      <geometry>
        <mesh filename="package://raider_description/meshes/arm_left/servo_upper_arm_left.dae" scale="0.001 0.001 0.001"/>
      </geometry>
    </collision>
    <visual>
      <origin rpy="0 0 0" xyz="0.04374  -4e-3 -118.94e-3"/>
      <geometry>
        <mesh filename="package://raider_description/meshes/arm_left/servo_upper_arm_left.dae" scale="0.001 0.001 0.001"/>
      </geometry>
    </visual>
    <inertial>
      <origin rpy="0 0 0" xyz="-0.076059296 3.228505e-3 308.337189e-3"/>
      <mass value="0.055"/>
      <inertia ixx="15.7877487408" ixy="-0.00765350004071" ixz="-0.618535858694" iyy="13.3731973321" iyz="-0.116966859215" izz="8.7856698187"/>
    </inertial>
  </link>
  <joint name="joint_servo_upperarm_union1_left" type="fixed">
    <dynamics damping="0.0" friction="10.0"/>
    <parent link="servo_upper_arm_left"/>
    <child link="union1_servo_left"/>
    <origin rpy="0 0 3.14159265359" xyz="0 0 0"/>
  </joint>
  <link name="union1_servo_left">
    <collision>
      <origin xyz="0.04374 -4e-3 -118.94e-3"/>
      <geometry>
        <mesh filename="package://raider_description/meshes/arm_left/union1_servo_left.dae" scale="0.001 0.001 0.001"/>
      </geometry>
    </collision>
    <visual>
      <origin xyz="0.04374 -4e-3 -118.94e-3"/>
      <geometry>
        <mesh filename="package://raider_description/meshes/arm_left/union1_servo_left.dae" scale="0.001 0.001 0.001"/>
      </geometry>
    </visual>
    <inertial>
      <origin rpy="0 0 0" xyz="-0.045191589 3.468790e-3 80.072578e-3"/>
      <mass value="4e-3"/>
      <inertia ixx="0.590627758" ixy="1.5e-07" ixz="0.019347738" iyy="0.251187499" iyz="0.00000012" izz="0.811914984"/>
    </inertial>
  </link>
  <joint name="joint_servo_upperarm_union2_left" type="fixed">
    <dynamics damping="0.0" friction="10.0"/>
    <parent link="servo_upper_arm_left"/>
    <child link="union2_servo_left"/>
    <origin rpy="0 0 3.14159265359" xyz="0 0 0"/>
  </joint>
  <link name="union2_servo_left">
    <collision>
      <origin xyz="0.04374 -4e-3 -118.94e-3"/>
      <geometry>
        <mesh filename="package://raider_description/meshes/arm_left/union2_servo_left.dae" scale="0.001 0.001 0.001"/>
      </geometry>
    </collision>
    <visual>
      <origin xyz="0.04374 -4e-3 -118.94e-3"/>
      <geometry>
        <mesh filename="package://raider_description/meshes/arm_left/union2_servo_left.dae" scale="0.001 0.001 0.001"/>
      </geometry>
    </visual>
    <inertial>
      <origin rpy="0 0 0" xyz="-0.045626991 3.451273e-3 75.296814e-3"/>
      <mass value="4e-3"/>
      <inertia ixx="0.255461633" ixy="-1.4093e-05" ixz="0.048831278" iyy="0.588954525" iyz="-0.000159133" izz="0.809321022"/>
    </inertial>
  </link>
  <joint name="joint_servo_elbowunion_left" type="fixed">
    <dynamics damping="0.0" friction="10.0"/>
    <parent link="union2_servo_left"/>
    <child link="servo_elbow_left"/>
    <origin xyz="0 0 0"/>
  </joint>
  <link name="servo_elbow_left">
    <collision>
      <origin xyz="0.04374 -4e-3 -118.94e-3"/>
      <geometry>
        <mesh filename="package://raider_description/meshes/arm_left/servo_elbow_left.dae" scale="0.001 0.001 0.001"/>
      </geometry>
    </collision>
    <visual>
      <origin xyz="0.04374 -4e-3 -118.94e-3"/>
      <geometry>
        <mesh filename="package://raider_description/meshes/arm_left/servo_elbow_left.dae" scale="0.001 0.001 0.001"/>
      </geometry>
    </visual>
    <inertial>
      <origin rpy="0 0 0" xyz="-0.048971466 3.471508e-3 49.196182e-3"/>
      <mass value="0.055"/>
      <inertia ixx="13.3028676946" ixy="0.00245297567846" ixz="-0.515734556249" iyy="15.8250571706" iyz="-0.0013934917261" izz="8.77893463349"/>
    </inertial>
  </link>
  <joint name="elbow_left" type="revolute">
    <dynamics damping="0.0" friction="0.0"/>
    <limit effort="100" lower="-2.09439510239" upper="2.09439510239" velocity="3"/>
    <parent link="servo_elbow_left"/>
    <child link="elbow_left"/>
    <origin rpy="0 0 0" xyz="0 -0.5e-3 -82.65e-3"/>
    <axis xyz="1 0 0"/>
  </joint>
  <link name="elbow_left">
    <collision>
      <origin xyz="0.04374 -3.5e-3 -36.29e-3"/>
      <geometry>
        <mesh filename="package://raider_description/meshes/arm_left/elbow_left.dae" scale="0.001 0.001 0.001"/>
      </geometry>
    </collision>
    <visual>
      <origin xyz="0.04374 -3.5e-3 -36.29e-3"/>
      <geometry>
        <mesh filename="package://raider_description/meshes/arm_left/elbow_left.dae" scale="0.001 0.001 0.001"/>
      </geometry>
    </visual>
    <inertial>
      <origin rpy="0 0 0" xyz="-0.0525494 7.686087e-3 26.149841e-3"/>
      <mass value="15e-3"/>
      <inertia ixx="4.397140534" ixy="0.245999243" ixz="0.927496479" iyy="8.263120442" iyz="-0.566498905" izz="6.876263573"/>
    </inertial>
  </link>
  <joint name="joint_elbow_forearm_left" type="fixed">
    <dynamics damping="0.0" friction="10.0"/>
    <parent link="elbow_left"/>
    <child link="forearm_left"/>
    <origin rpy="0 0 0" xyz="0 0 0"/>
  </joint>
  <link name="forearm_left">
    <collision>
      <origin xyz="0.04374 -3.5e-3 -36.29e-3"/>
      <geometry>
        <mesh filename="package://raider_description/meshes/arm_left/forearm_left.dae" scale="0.001 0.001 0.001"/>
      </geometry>
    </collision>
    <visual>
      <origin xyz="0.04374 -3.5e-3 -36.29e-3"/>
      <geometry>
        <mesh filename="package://raider_description/meshes/arm_left/forearm_left.dae" scale="0.001 0.001 0.001"/>
      </geometry>
    </visual>
    <inertial>
      <origin rpy="0 0 0" xyz="-0.053241585 6.205578e-3 -1.415684e-3"/>
      <mass value="14e-3"/>
      <inertia ixx="3.440210914" ixy="0.018232757" ixz="0.095159818" iyy="4.001844032" iyz="0.207159085" izz="4.51976604"/>
    </inertial>
  </link>
  <joint name="joint_sharp_forearm_left" type="fixed">
    <dynamics damping="0.0" friction="10.0"/>
    <parent link="forearm_left"/>
    <child link="sharp_left"/>
    <origin rpy="0 0 -1.57079632679" xyz="0.00403 -11.08e-3 -46.51e-3"/>
  </joint>
  <link name="sharp_left">
    <collision>
      <origin rpy="0 0 1.57079632679" xyz="-11.08e-3 0.04097 10.22e-3"/>
      <geometry>
        <mesh filename="package://raider_description/meshes/arm_left/sharp_left.dae" scale="0.001 0.001 0.001"/>
      </geometry>
    </collision>
    <visual>
      <origin rpy="0 0 1.57079632679" xyz="-11.08e-3 0.04097 10.22e-3"/>
      <geometry>
        <mesh filename="package://raider_description/meshes/arm_left/sharp_left.dae" scale="0.001 0.001 0.001"/>
      </geometry>
    </visual>
    <inertial>
      <origin rpy="0 0 0" xyz="-0.055055099 -1.675636e-3 -6.841179e-3"/>
      <mass value="3.5e-3"/>
      <inertia ixx="0.084903021" ixy="0.00951706" ixz="0.023015952" iyy="0.338559496" iyz="0.006557898" izz="0.325236131"/>
    </inertial>
  </link>
  <joint name="joint_forearm_hand_left" type="fixed">
    <parent link="forearm_left"/>
    <child link="hand_left"/>
    <origin rpy="0 0 0" xyz="0 0 0"/>
  </joint>
  <link name="hand_left">
    <collision>
      <origin xyz="0.04374 -3.5e-3 -36.29e-3"/>
      <geometry>
        <mesh filename="package://raider_description/meshes/arm_left/hand_left.dae" scale="0.001 0.001 0.001"/>
      </geometry>
    </collision>
    <visual>
      <origin xyz="0.04374 -3.5e-3 -36.29e-3"/>
      <geometry>
        <mesh filename="package://raider_description/meshes/arm_left/hand_left.dae" scale="0.001 0.001 0.001"/>
      </geometry>
    </visual>
    <inertial>
      <origin rpy="0 0 0" xyz="-0.057381317 7.527186e-3 -48.516449e-3"/>
      <mass value="34e-3"/>
      <inertia ixx="13.839519597" ixy="-0.01601312" ixz="-0.690764395" iyy="13.107441542" iyz="-0.183076833" izz="6.004466355"/>
    </inertial>
  </link>
</robot>

